[2020-04-28 10:15:33,408][MainThread:14852][task_id:django.utils.autoreload][autoreload.py:598][INFO][Watching for file changes with StatReloader]
[2020-04-28 10:16:38,942][MainThread:4508][task_id:django.utils.autoreload][autoreload.py:598][INFO][Watching for file changes with StatReloader]
[2020-04-28 10:17:28,302][Thread-1:14656][task_id:root][views.py:50][ERROR][猜猜我是谁！！！]
[2020-04-28 10:18:15,314][MainThread:4508][task_id:django.utils.autoreload][autoreload.py:222][INFO][D:\python_files\PythonProject\Site\Blog\views.py changed, reloading.]
[2020-04-28 10:18:16,030][MainThread:17028][task_id:django.utils.autoreload][autoreload.py:598][INFO][Watching for file changes with StatReloader]
[2020-04-28 21:32:51,647][MainThread:11044][task_id:elasticsearch][base.py:122][INFO][HEAD http://localhost:9200/ [status:200 request:0.081s]]
[2020-04-28 21:32:51,655][MainThread:11044][task_id:elasticsearch][base.py:122][INFO][HEAD http://localhost:9200/blog [status:200 request:0.006s]]
[2020-04-28 21:32:51,657][MainThread:11044][task_id:elasticsearch][base.py:122][INFO][HEAD http://localhost:9200/ [status:200 request:0.001s]]
[2020-04-28 21:32:51,658][MainThread:11044][task_id:elasticsearch][base.py:122][INFO][HEAD http://localhost:9200/suggestion_db [status:200 request:0.002s]]
[2020-04-28 21:32:56,706][MainThread:10204][task_id:elasticsearch][base.py:122][INFO][HEAD http://localhost:9200/ [status:200 request:0.009s]]
[2020-04-28 21:32:56,708][MainThread:10204][task_id:elasticsearch][base.py:122][INFO][HEAD http://localhost:9200/blog [status:200 request:0.002s]]
[2020-04-28 21:32:56,710][MainThread:10204][task_id:elasticsearch][base.py:122][INFO][HEAD http://localhost:9200/ [status:200 request:0.002s]]
[2020-04-28 21:32:56,712][MainThread:10204][task_id:elasticsearch][base.py:122][INFO][HEAD http://localhost:9200/suggestion_db [status:200 request:0.002s]]
[2020-04-28 21:33:11,582][MainThread:11780][task_id:elasticsearch][base.py:122][INFO][HEAD http://localhost:9200/ [status:200 request:0.016s]]
[2020-04-28 21:33:11,584][MainThread:11780][task_id:elasticsearch][base.py:122][INFO][HEAD http://localhost:9200/blog [status:200 request:0.002s]]
[2020-04-28 21:33:11,586][MainThread:11780][task_id:elasticsearch][base.py:122][INFO][HEAD http://localhost:9200/ [status:200 request:0.001s]]
[2020-04-28 21:33:11,588][MainThread:11780][task_id:elasticsearch][base.py:122][INFO][HEAD http://localhost:9200/suggestion_db [status:200 request:0.002s]]
[2020-04-28 21:33:12,250][MainThread:16704][task_id:elasticsearch][base.py:122][INFO][HEAD http://localhost:9200/ [status:200 request:0.016s]]
[2020-04-28 21:33:12,252][MainThread:16704][task_id:elasticsearch][base.py:122][INFO][HEAD http://localhost:9200/blog [status:200 request:0.002s]]
[2020-04-28 21:33:12,253][MainThread:16704][task_id:elasticsearch][base.py:122][INFO][HEAD http://localhost:9200/ [status:200 request:0.002s]]
[2020-04-28 21:33:12,256][MainThread:16704][task_id:elasticsearch][base.py:122][INFO][HEAD http://localhost:9200/suggestion_db [status:200 request:0.002s]]
[2020-04-28 21:33:12,482][MainThread:16704][task_id:django.utils.autoreload][autoreload.py:598][INFO][Watching for file changes with StatReloader]
[2020-04-28 21:46:35,049][Thread-1:19524][task_id:elasticsearch][base.py:122][INFO][GET http://localhost:9200/suggestion_db/_search?filter_path=suggest.my_suggestion.options.text [status:200 request:0.115s]]
[2020-04-28 21:46:42,219][Thread-3:20176][task_id:elasticsearch][base.py:122][INFO][GET http://localhost:9200/blog/_search?filter_path=hits.total%2Chits.hits._id%2Chits.hits.highlight [status:200 request:0.090s]]
[2020-04-28 21:47:47,284][Thread-3:20176][task_id:elasticsearch][base.py:122][INFO][GET http://localhost:9200/suggestion_db/_search?filter_path=suggest.my_suggestion.options.text [status:200 request:0.009s]]
[2020-04-28 21:47:50,079][Thread-1:19524][task_id:elasticsearch][base.py:122][INFO][GET http://localhost:9200/blog/_search?filter_path=hits.total%2Chits.hits._id%2Chits.hits.highlight [status:200 request:0.037s]]
[2020-04-28 21:47:53,504][Thread-1:19524][task_id:elasticsearch][base.py:122][INFO][GET http://localhost:9200/blog/_search?filter_path=hits.total%2Chits.hits._id%2Chits.hits.highlight [status:200 request:0.022s]]
[2020-04-28 21:47:56,541][Thread-3:20176][task_id:elasticsearch][base.py:122][INFO][GET http://localhost:9200/blog/_search?filter_path=hits.total%2Chits.hits._id%2Chits.hits.highlight [status:200 request:0.018s]]
[2020-04-28 21:53:27,380][MainThread:16704][task_id:django.utils.autoreload][autoreload.py:222][INFO][D:\python_files\PythonProject\Site\utils\es.py changed, reloading.]
[2020-04-28 21:53:27,999][MainThread:10568][task_id:elasticsearch][base.py:122][INFO][HEAD http://localhost:9200/ [status:200 request:0.009s]]
[2020-04-28 21:53:28,002][MainThread:10568][task_id:elasticsearch][base.py:122][INFO][HEAD http://localhost:9200/blog [status:200 request:0.003s]]
[2020-04-28 21:53:28,003][MainThread:10568][task_id:elasticsearch][base.py:122][INFO][HEAD http://localhost:9200/ [status:200 request:0.001s]]
[2020-04-28 21:53:28,005][MainThread:10568][task_id:elasticsearch][base.py:122][INFO][HEAD http://localhost:9200/suggestion_db [status:200 request:0.002s]]
[2020-04-28 21:53:28,212][MainThread:10568][task_id:django.utils.autoreload][autoreload.py:598][INFO][Watching for file changes with StatReloader]
[2020-04-28 21:53:33,556][Thread-1:8744][task_id:elasticsearch][base.py:122][INFO][GET http://localhost:9200/suggestion_db/_search?filter_path=suggest.my_suggestion.options.text [status:200 request:0.007s]]
[2020-04-28 21:53:35,423][Thread-1:8744][task_id:elasticsearch][base.py:122][INFO][GET http://localhost:9200/blog/_search?filter_path=hits.total%2Chits.hits._id%2Chits.hits.highlight [status:200 request:0.012s]]
[2020-04-28 21:55:56,731][Thread-1:8744][task_id:elasticsearch][base.py:122][INFO][GET http://localhost:9200/suggestion_db/_search?filter_path=suggest.my_suggestion.options.text [status:200 request:0.005s]]
[2020-04-28 21:55:57,222][Thread-1:8744][task_id:elasticsearch][base.py:122][INFO][GET http://localhost:9200/suggestion_db/_search?filter_path=suggest.my_suggestion.options.text [status:200 request:0.016s]]
[2020-04-28 21:55:57,718][Thread-1:8744][task_id:elasticsearch][base.py:122][INFO][GET http://localhost:9200/suggestion_db/_search?filter_path=suggest.my_suggestion.options.text [status:200 request:0.016s]]
[2020-04-28 21:55:59,355][Thread-1:8744][task_id:elasticsearch][base.py:122][INFO][GET http://localhost:9200/suggestion_db/_search?filter_path=suggest.my_suggestion.options.text [status:200 request:0.005s]]
[2020-04-28 21:56:01,751][Thread-3:2596][task_id:elasticsearch][base.py:122][INFO][GET http://localhost:9200/blog/_search?filter_path=hits.total%2Chits.hits._id%2Chits.hits.highlight [status:200 request:0.010s]]
[2020-04-28 21:58:11,377][Thread-3:2596][task_id:elasticsearch][base.py:122][INFO][GET http://localhost:9200/suggestion_db/_search?filter_path=suggest.my_suggestion.options.text [status:200 request:0.004s]]
[2020-04-28 21:58:12,892][Thread-1:8744][task_id:elasticsearch][base.py:122][INFO][GET http://localhost:9200/blog/_search?filter_path=hits.total%2Chits.hits._id%2Chits.hits.highlight [status:200 request:0.017s]]
[2020-04-28 21:58:54,709][MainThread:10568][task_id:django.utils.autoreload][autoreload.py:222][INFO][D:\python_files\PythonProject\Site\utils\es.py changed, reloading.]
[2020-04-28 21:58:55,177][MainThread:20424][task_id:elasticsearch][base.py:122][INFO][HEAD http://localhost:9200/ [status:200 request:0.010s]]
[2020-04-28 21:58:55,179][MainThread:20424][task_id:elasticsearch][base.py:122][INFO][HEAD http://localhost:9200/blog [status:200 request:0.002s]]
[2020-04-28 21:58:55,181][MainThread:20424][task_id:elasticsearch][base.py:122][INFO][HEAD http://localhost:9200/ [status:200 request:0.002s]]
[2020-04-28 21:58:55,182][MainThread:20424][task_id:elasticsearch][base.py:122][INFO][HEAD http://localhost:9200/suggestion_db [status:200 request:0.001s]]
[2020-04-28 21:58:55,380][MainThread:20424][task_id:django.utils.autoreload][autoreload.py:598][INFO][Watching for file changes with StatReloader]
[2020-04-28 21:59:05,270][MainThread:20424][task_id:django.utils.autoreload][autoreload.py:222][INFO][D:\python_files\PythonProject\Site\utils\es.py changed, reloading.]
[2020-04-28 21:59:05,873][MainThread:2404][task_id:elasticsearch][base.py:122][INFO][HEAD http://localhost:9200/ [status:200 request:0.011s]]
[2020-04-28 21:59:05,875][MainThread:2404][task_id:elasticsearch][base.py:122][INFO][HEAD http://localhost:9200/blog [status:200 request:0.001s]]
[2020-04-28 21:59:05,878][MainThread:2404][task_id:elasticsearch][base.py:122][INFO][HEAD http://localhost:9200/ [status:200 request:0.002s]]
[2020-04-28 21:59:05,880][MainThread:2404][task_id:elasticsearch][base.py:122][INFO][HEAD http://localhost:9200/suggestion_db [status:200 request:0.002s]]
[2020-04-28 21:59:06,125][MainThread:2404][task_id:django.utils.autoreload][autoreload.py:598][INFO][Watching for file changes with StatReloader]
[2020-04-28 22:01:26,206][Thread-1:7976][task_id:elasticsearch][base.py:122][INFO][GET http://localhost:9200/suggestion_db/_search?filter_path=suggest.my_suggestion.options.text [status:200 request:0.007s]]
[2020-04-28 22:01:27,526][Thread-1:7976][task_id:elasticsearch][base.py:122][INFO][GET http://localhost:9200/blog/_search?filter_path=hits.total%2Chits.hits._id%2Chits.hits.highlight [status:200 request:0.011s]]
[2020-04-28 23:02:57,874][Thread-12:20252][task_id:django.request][log.py:228][WARNING][Forbidden: /app01/bloglist/]
[2020-04-29 07:52:02,277][MainThread:13128][task_id:elasticsearch][base.py:122][INFO][HEAD http://localhost:9200/ [status:200 request:0.096s]]
[2020-04-29 07:52:02,285][MainThread:13128][task_id:elasticsearch][base.py:122][INFO][HEAD http://localhost:9200/blog [status:200 request:0.008s]]
[2020-04-29 07:52:02,285][MainThread:13128][task_id:elasticsearch][base.py:122][INFO][HEAD http://localhost:9200/ [status:200 request:0.000s]]
[2020-04-29 07:52:02,294][MainThread:13128][task_id:elasticsearch][base.py:122][INFO][HEAD http://localhost:9200/suggestion_db [status:200 request:0.008s]]
[2020-04-29 07:52:03,108][MainThread:14068][task_id:elasticsearch][base.py:122][INFO][HEAD http://localhost:9200/ [status:200 request:0.016s]]
[2020-04-29 07:52:03,108][MainThread:14068][task_id:elasticsearch][base.py:122][INFO][HEAD http://localhost:9200/blog [status:200 request:0.000s]]
[2020-04-29 07:52:03,116][MainThread:14068][task_id:elasticsearch][base.py:122][INFO][HEAD http://localhost:9200/ [status:200 request:0.008s]]
[2020-04-29 07:52:03,116][MainThread:14068][task_id:elasticsearch][base.py:122][INFO][HEAD http://localhost:9200/suggestion_db [status:200 request:0.000s]]
[2020-04-29 07:52:03,341][MainThread:14068][task_id:django.utils.autoreload][autoreload.py:598][INFO][Watching for file changes with StatReloader]
[2020-04-29 08:22:55,876][MainThread:2820][task_id:elasticsearch][base.py:122][INFO][HEAD http://localhost:9200/ [status:200 request:0.073s]]
[2020-04-29 08:22:55,876][MainThread:2820][task_id:elasticsearch][base.py:122][INFO][HEAD http://localhost:9200/blog [status:200 request:0.000s]]
[2020-04-29 08:22:55,876][MainThread:2820][task_id:elasticsearch][base.py:122][INFO][HEAD http://localhost:9200/ [status:200 request:0.000s]]
[2020-04-29 08:22:55,876][MainThread:2820][task_id:elasticsearch][base.py:122][INFO][HEAD http://localhost:9200/suggestion_db [status:200 request:0.000s]]
[2020-04-29 08:22:56,489][MainThread:14584][task_id:elasticsearch][base.py:122][INFO][HEAD http://localhost:9200/ [status:200 request:0.016s]]
[2020-04-29 08:22:56,489][MainThread:14584][task_id:elasticsearch][base.py:122][INFO][HEAD http://localhost:9200/blog [status:200 request:0.000s]]
[2020-04-29 08:22:56,489][MainThread:14584][task_id:elasticsearch][base.py:122][INFO][HEAD http://localhost:9200/ [status:200 request:0.000s]]
[2020-04-29 08:22:56,489][MainThread:14584][task_id:elasticsearch][base.py:122][INFO][HEAD http://localhost:9200/suggestion_db [status:200 request:0.000s]]
[2020-04-29 08:22:56,693][MainThread:14584][task_id:django.utils.autoreload][autoreload.py:598][INFO][Watching for file changes with StatReloader]
[2020-04-29 08:50:11,916][MainThread:5420][task_id:django.utils.autoreload][autoreload.py:598][INFO][Watching for file changes with StatReloader]
[2020-04-29 08:55:31,175][MainThread:5420][task_id:django.utils.autoreload][autoreload.py:222][INFO][D:\python_files\PythonProject\Site\Site\settings.py changed, reloading.]
[2020-04-29 08:55:31,875][MainThread:7908][task_id:django.utils.autoreload][autoreload.py:598][INFO][Watching for file changes with StatReloader]
[2020-04-29 08:55:41,414][MainThread:7908][task_id:django.utils.autoreload][autoreload.py:222][INFO][D:\python_files\PythonProject\Site\utils\es.py changed, reloading.]
[2020-04-29 08:55:45,972][MainThread:12232][task_id:elasticsearch][base.py:150][WARNING][HEAD http://localhost:9200/ [status:N/A request:4.072s]]
Traceback (most recent call last):
  File "D:\program_files\py_virtual_envs\env_myblog\lib\site-packages\urllib3\connection.py", line 157, in _new_conn
    (self._dns_host, self.port), self.timeout, **extra_kw
  File "D:\program_files\py_virtual_envs\env_myblog\lib\site-packages\urllib3\util\connection.py", line 84, in create_connection
    raise err
  File "D:\program_files\py_virtual_envs\env_myblog\lib\site-packages\urllib3\util\connection.py", line 74, in create_connection
    sock.connect(sa)
ConnectionRefusedError: [WinError 10061] 由于目标计算机积极拒绝，无法连接。

During handling of the above exception, another exception occurred:

Traceback (most recent call last):
  File "D:\program_files\py_virtual_envs\env_myblog\lib\site-packages\elasticsearch\connection\http_urllib3.py", line 242, in perform_request
    method, url, body, retries=Retry(False), headers=request_headers, **kw
  File "D:\program_files\py_virtual_envs\env_myblog\lib\site-packages\urllib3\connectionpool.py", line 720, in urlopen
    method, url, error=e, _pool=self, _stacktrace=sys.exc_info()[2]
  File "D:\program_files\py_virtual_envs\env_myblog\lib\site-packages\urllib3\util\retry.py", line 376, in increment
    raise six.reraise(type(error), error, _stacktrace)
  File "D:\program_files\py_virtual_envs\env_myblog\lib\site-packages\urllib3\packages\six.py", line 735, in reraise
    raise value
  File "D:\program_files\py_virtual_envs\env_myblog\lib\site-packages\urllib3\connectionpool.py", line 672, in urlopen
    chunked=chunked,
  File "D:\program_files\py_virtual_envs\env_myblog\lib\site-packages\urllib3\connectionpool.py", line 387, in _make_request
    conn.request(method, url, **httplib_request_kw)
  File "d:\program_files\python3.7.6\lib\http\client.py", line 1252, in request
    self._send_request(method, url, body, headers, encode_chunked)
  File "d:\program_files\python3.7.6\lib\http\client.py", line 1298, in _send_request
    self.endheaders(body, encode_chunked=encode_chunked)
  File "d:\program_files\python3.7.6\lib\http\client.py", line 1247, in endheaders
    self._send_output(message_body, encode_chunked=encode_chunked)
  File "d:\program_files\python3.7.6\lib\http\client.py", line 1026, in _send_output
    self.send(msg)
  File "d:\program_files\python3.7.6\lib\http\client.py", line 966, in send
    self.connect()
  File "D:\program_files\py_virtual_envs\env_myblog\lib\site-packages\urllib3\connection.py", line 184, in connect
    conn = self._new_conn()
  File "D:\program_files\py_virtual_envs\env_myblog\lib\site-packages\urllib3\connection.py", line 169, in _new_conn
    self, "Failed to establish a new connection: %s" % e
urllib3.exceptions.NewConnectionError: <urllib3.connection.HTTPConnection object at 0x0000018860E30CC8>: Failed to establish a new connection: [WinError 10061] 由于目标计算机积极拒绝，无法连接。
[2020-04-29 08:55:50,064][MainThread:12232][task_id:elasticsearch][base.py:150][WARNING][HEAD http://localhost:9200/ [status:N/A request:4.083s]]
Traceback (most recent call last):
  File "D:\program_files\py_virtual_envs\env_myblog\lib\site-packages\urllib3\connection.py", line 157, in _new_conn
    (self._dns_host, self.port), self.timeout, **extra_kw
  File "D:\program_files\py_virtual_envs\env_myblog\lib\site-packages\urllib3\util\connection.py", line 84, in create_connection
    raise err
  File "D:\program_files\py_virtual_envs\env_myblog\lib\site-packages\urllib3\util\connection.py", line 74, in create_connection
    sock.connect(sa)
ConnectionRefusedError: [WinError 10061] 由于目标计算机积极拒绝，无法连接。

During handling of the above exception, another exception occurred:

Traceback (most recent call last):
  File "D:\program_files\py_virtual_envs\env_myblog\lib\site-packages\elasticsearch\connection\http_urllib3.py", line 242, in perform_request
    method, url, body, retries=Retry(False), headers=request_headers, **kw
  File "D:\program_files\py_virtual_envs\env_myblog\lib\site-packages\urllib3\connectionpool.py", line 720, in urlopen
    method, url, error=e, _pool=self, _stacktrace=sys.exc_info()[2]
  File "D:\program_files\py_virtual_envs\env_myblog\lib\site-packages\urllib3\util\retry.py", line 376, in increment
    raise six.reraise(type(error), error, _stacktrace)
  File "D:\program_files\py_virtual_envs\env_myblog\lib\site-packages\urllib3\packages\six.py", line 735, in reraise
    raise value
  File "D:\program_files\py_virtual_envs\env_myblog\lib\site-packages\urllib3\connectionpool.py", line 672, in urlopen
    chunked=chunked,
  File "D:\program_files\py_virtual_envs\env_myblog\lib\site-packages\urllib3\connectionpool.py", line 387, in _make_request
    conn.request(method, url, **httplib_request_kw)
  File "d:\program_files\python3.7.6\lib\http\client.py", line 1252, in request
    self._send_request(method, url, body, headers, encode_chunked)
  File "d:\program_files\python3.7.6\lib\http\client.py", line 1298, in _send_request
    self.endheaders(body, encode_chunked=encode_chunked)
  File "d:\program_files\python3.7.6\lib\http\client.py", line 1247, in endheaders
    self._send_output(message_body, encode_chunked=encode_chunked)
  File "d:\program_files\python3.7.6\lib\http\client.py", line 1026, in _send_output
    self.send(msg)
  File "d:\program_files\python3.7.6\lib\http\client.py", line 966, in send
    self.connect()
  File "D:\program_files\py_virtual_envs\env_myblog\lib\site-packages\urllib3\connection.py", line 184, in connect
    conn = self._new_conn()
  File "D:\program_files\py_virtual_envs\env_myblog\lib\site-packages\urllib3\connection.py", line 169, in _new_conn
    self, "Failed to establish a new connection: %s" % e
urllib3.exceptions.NewConnectionError: <urllib3.connection.HTTPConnection object at 0x0000018860E49B08>: Failed to establish a new connection: [WinError 10061] 由于目标计算机积极拒绝，无法连接。
[2020-04-29 08:56:05,142][MainThread:13956][task_id:elasticsearch][base.py:150][WARNING][HEAD http://localhost:9200/ [status:N/A request:4.070s]]
Traceback (most recent call last):
  File "D:\program_files\py_virtual_envs\env_myblog\lib\site-packages\urllib3\connection.py", line 157, in _new_conn
    (self._dns_host, self.port), self.timeout, **extra_kw
  File "D:\program_files\py_virtual_envs\env_myblog\lib\site-packages\urllib3\util\connection.py", line 84, in create_connection
    raise err
  File "D:\program_files\py_virtual_envs\env_myblog\lib\site-packages\urllib3\util\connection.py", line 74, in create_connection
    sock.connect(sa)
ConnectionRefusedError: [WinError 10061] 由于目标计算机积极拒绝，无法连接。

During handling of the above exception, another exception occurred:

Traceback (most recent call last):
  File "D:\program_files\py_virtual_envs\env_myblog\lib\site-packages\elasticsearch\connection\http_urllib3.py", line 242, in perform_request
    method, url, body, retries=Retry(False), headers=request_headers, **kw
  File "D:\program_files\py_virtual_envs\env_myblog\lib\site-packages\urllib3\connectionpool.py", line 720, in urlopen
    method, url, error=e, _pool=self, _stacktrace=sys.exc_info()[2]
  File "D:\program_files\py_virtual_envs\env_myblog\lib\site-packages\urllib3\util\retry.py", line 376, in increment
    raise six.reraise(type(error), error, _stacktrace)
  File "D:\program_files\py_virtual_envs\env_myblog\lib\site-packages\urllib3\packages\six.py", line 735, in reraise
    raise value
  File "D:\program_files\py_virtual_envs\env_myblog\lib\site-packages\urllib3\connectionpool.py", line 672, in urlopen
    chunked=chunked,
  File "D:\program_files\py_virtual_envs\env_myblog\lib\site-packages\urllib3\connectionpool.py", line 387, in _make_request
    conn.request(method, url, **httplib_request_kw)
  File "d:\program_files\python3.7.6\lib\http\client.py", line 1252, in request
    self._send_request(method, url, body, headers, encode_chunked)
  File "d:\program_files\python3.7.6\lib\http\client.py", line 1298, in _send_request
    self.endheaders(body, encode_chunked=encode_chunked)
  File "d:\program_files\python3.7.6\lib\http\client.py", line 1247, in endheaders
    self._send_output(message_body, encode_chunked=encode_chunked)
  File "d:\program_files\python3.7.6\lib\http\client.py", line 1026, in _send_output
    self.send(msg)
  File "d:\program_files\python3.7.6\lib\http\client.py", line 966, in send
    self.connect()
  File "D:\program_files\py_virtual_envs\env_myblog\lib\site-packages\urllib3\connection.py", line 184, in connect
    conn = self._new_conn()
  File "D:\program_files\py_virtual_envs\env_myblog\lib\site-packages\urllib3\connection.py", line 169, in _new_conn
    self, "Failed to establish a new connection: %s" % e
urllib3.exceptions.NewConnectionError: <urllib3.connection.HTTPConnection object at 0x0000015AFE508248>: Failed to establish a new connection: [WinError 10061] 由于目标计算机积极拒绝，无法连接。
[2020-04-29 08:56:09,211][MainThread:13956][task_id:elasticsearch][base.py:150][WARNING][HEAD http://localhost:9200/ [status:N/A request:4.068s]]
Traceback (most recent call last):
  File "D:\program_files\py_virtual_envs\env_myblog\lib\site-packages\urllib3\connection.py", line 157, in _new_conn
    (self._dns_host, self.port), self.timeout, **extra_kw
  File "D:\program_files\py_virtual_envs\env_myblog\lib\site-packages\urllib3\util\connection.py", line 84, in create_connection
    raise err
  File "D:\program_files\py_virtual_envs\env_myblog\lib\site-packages\urllib3\util\connection.py", line 74, in create_connection
    sock.connect(sa)
ConnectionRefusedError: [WinError 10061] 由于目标计算机积极拒绝，无法连接。

During handling of the above exception, another exception occurred:

Traceback (most recent call last):
  File "D:\program_files\py_virtual_envs\env_myblog\lib\site-packages\elasticsearch\connection\http_urllib3.py", line 242, in perform_request
    method, url, body, retries=Retry(False), headers=request_headers, **kw
  File "D:\program_files\py_virtual_envs\env_myblog\lib\site-packages\urllib3\connectionpool.py", line 720, in urlopen
    method, url, error=e, _pool=self, _stacktrace=sys.exc_info()[2]
  File "D:\program_files\py_virtual_envs\env_myblog\lib\site-packages\urllib3\util\retry.py", line 376, in increment
    raise six.reraise(type(error), error, _stacktrace)
  File "D:\program_files\py_virtual_envs\env_myblog\lib\site-packages\urllib3\packages\six.py", line 735, in reraise
    raise value
  File "D:\program_files\py_virtual_envs\env_myblog\lib\site-packages\urllib3\connectionpool.py", line 672, in urlopen
    chunked=chunked,
  File "D:\program_files\py_virtual_envs\env_myblog\lib\site-packages\urllib3\connectionpool.py", line 387, in _make_request
    conn.request(method, url, **httplib_request_kw)
  File "d:\program_files\python3.7.6\lib\http\client.py", line 1252, in request
    self._send_request(method, url, body, headers, encode_chunked)
  File "d:\program_files\python3.7.6\lib\http\client.py", line 1298, in _send_request
    self.endheaders(body, encode_chunked=encode_chunked)
  File "d:\program_files\python3.7.6\lib\http\client.py", line 1247, in endheaders
    self._send_output(message_body, encode_chunked=encode_chunked)
  File "d:\program_files\python3.7.6\lib\http\client.py", line 1026, in _send_output
    self.send(msg)
  File "d:\program_files\python3.7.6\lib\http\client.py", line 966, in send
    self.connect()
  File "D:\program_files\py_virtual_envs\env_myblog\lib\site-packages\urllib3\connection.py", line 184, in connect
    conn = self._new_conn()
  File "D:\program_files\py_virtual_envs\env_myblog\lib\site-packages\urllib3\connection.py", line 169, in _new_conn
    self, "Failed to establish a new connection: %s" % e
urllib3.exceptions.NewConnectionError: <urllib3.connection.HTTPConnection object at 0x0000015AFE5220C8>: Failed to establish a new connection: [WinError 10061] 由于目标计算机积极拒绝，无法连接。
[2020-04-29 08:56:13,385][MainThread:13956][task_id:elasticsearch][base.py:122][INFO][HEAD http://localhost:9200/ [status:200 request:4.174s]]
[2020-04-29 08:56:13,402][MainThread:13956][task_id:elasticsearch][base.py:122][INFO][HEAD http://localhost:9200/blog [status:200 request:0.017s]]
[2020-04-29 08:56:13,402][MainThread:13956][task_id:elasticsearch][base.py:122][INFO][HEAD http://localhost:9200/ [status:200 request:0.000s]]
[2020-04-29 08:56:13,402][MainThread:13956][task_id:elasticsearch][base.py:122][INFO][HEAD http://localhost:9200/suggestion_db [status:200 request:0.000s]]
[2020-04-29 08:56:14,096][MainThread:2948][task_id:elasticsearch][base.py:122][INFO][HEAD http://localhost:9200/ [status:200 request:0.016s]]
[2020-04-29 08:56:14,096][MainThread:2948][task_id:elasticsearch][base.py:122][INFO][HEAD http://localhost:9200/blog [status:200 request:0.000s]]
[2020-04-29 08:56:14,096][MainThread:2948][task_id:elasticsearch][base.py:122][INFO][HEAD http://localhost:9200/ [status:200 request:0.000s]]
[2020-04-29 08:56:14,112][MainThread:2948][task_id:elasticsearch][base.py:122][INFO][HEAD http://localhost:9200/suggestion_db [status:200 request:0.016s]]
[2020-04-29 08:56:14,348][MainThread:2948][task_id:django.utils.autoreload][autoreload.py:598][INFO][Watching for file changes with StatReloader]
[2020-04-29 08:57:16,446][MainThread:6288][task_id:elasticsearch][base.py:150][WARNING][HEAD http://localhost:9200/ [status:N/A request:4.093s]]
Traceback (most recent call last):
  File "D:\program_files\py_virtual_envs\env_myblog\lib\site-packages\urllib3\connection.py", line 157, in _new_conn
    (self._dns_host, self.port), self.timeout, **extra_kw
  File "D:\program_files\py_virtual_envs\env_myblog\lib\site-packages\urllib3\util\connection.py", line 84, in create_connection
    raise err
  File "D:\program_files\py_virtual_envs\env_myblog\lib\site-packages\urllib3\util\connection.py", line 74, in create_connection
    sock.connect(sa)
ConnectionRefusedError: [WinError 10061] 由于目标计算机积极拒绝，无法连接。

During handling of the above exception, another exception occurred:

Traceback (most recent call last):
  File "D:\program_files\py_virtual_envs\env_myblog\lib\site-packages\elasticsearch\connection\http_urllib3.py", line 242, in perform_request
    method, url, body, retries=Retry(False), headers=request_headers, **kw
  File "D:\program_files\py_virtual_envs\env_myblog\lib\site-packages\urllib3\connectionpool.py", line 720, in urlopen
    method, url, error=e, _pool=self, _stacktrace=sys.exc_info()[2]
  File "D:\program_files\py_virtual_envs\env_myblog\lib\site-packages\urllib3\util\retry.py", line 376, in increment
    raise six.reraise(type(error), error, _stacktrace)
  File "D:\program_files\py_virtual_envs\env_myblog\lib\site-packages\urllib3\packages\six.py", line 735, in reraise
    raise value
  File "D:\program_files\py_virtual_envs\env_myblog\lib\site-packages\urllib3\connectionpool.py", line 672, in urlopen
    chunked=chunked,
  File "D:\program_files\py_virtual_envs\env_myblog\lib\site-packages\urllib3\connectionpool.py", line 387, in _make_request
    conn.request(method, url, **httplib_request_kw)
  File "d:\program_files\python3.7.6\lib\http\client.py", line 1252, in request
    self._send_request(method, url, body, headers, encode_chunked)
  File "d:\program_files\python3.7.6\lib\http\client.py", line 1298, in _send_request
    self.endheaders(body, encode_chunked=encode_chunked)
  File "d:\program_files\python3.7.6\lib\http\client.py", line 1247, in endheaders
    self._send_output(message_body, encode_chunked=encode_chunked)
  File "d:\program_files\python3.7.6\lib\http\client.py", line 1026, in _send_output
    self.send(msg)
  File "d:\program_files\python3.7.6\lib\http\client.py", line 966, in send
    self.connect()
  File "D:\program_files\py_virtual_envs\env_myblog\lib\site-packages\urllib3\connection.py", line 184, in connect
    conn = self._new_conn()
  File "D:\program_files\py_virtual_envs\env_myblog\lib\site-packages\urllib3\connection.py", line 169, in _new_conn
    self, "Failed to establish a new connection: %s" % e
urllib3.exceptions.NewConnectionError: <urllib3.connection.HTTPConnection object at 0x0000020015EF8388>: Failed to establish a new connection: [WinError 10061] 由于目标计算机积极拒绝，无法连接。
[2020-04-29 08:57:20,543][MainThread:6288][task_id:elasticsearch][base.py:150][WARNING][HEAD http://localhost:9200/ [status:N/A request:4.098s]]
Traceback (most recent call last):
  File "D:\program_files\py_virtual_envs\env_myblog\lib\site-packages\urllib3\connection.py", line 157, in _new_conn
    (self._dns_host, self.port), self.timeout, **extra_kw
  File "D:\program_files\py_virtual_envs\env_myblog\lib\site-packages\urllib3\util\connection.py", line 84, in create_connection
    raise err
  File "D:\program_files\py_virtual_envs\env_myblog\lib\site-packages\urllib3\util\connection.py", line 74, in create_connection
    sock.connect(sa)
ConnectionRefusedError: [WinError 10061] 由于目标计算机积极拒绝，无法连接。

During handling of the above exception, another exception occurred:

Traceback (most recent call last):
  File "D:\program_files\py_virtual_envs\env_myblog\lib\site-packages\elasticsearch\connection\http_urllib3.py", line 242, in perform_request
    method, url, body, retries=Retry(False), headers=request_headers, **kw
  File "D:\program_files\py_virtual_envs\env_myblog\lib\site-packages\urllib3\connectionpool.py", line 720, in urlopen
    method, url, error=e, _pool=self, _stacktrace=sys.exc_info()[2]
  File "D:\program_files\py_virtual_envs\env_myblog\lib\site-packages\urllib3\util\retry.py", line 376, in increment
    raise six.reraise(type(error), error, _stacktrace)
  File "D:\program_files\py_virtual_envs\env_myblog\lib\site-packages\urllib3\packages\six.py", line 735, in reraise
    raise value
  File "D:\program_files\py_virtual_envs\env_myblog\lib\site-packages\urllib3\connectionpool.py", line 672, in urlopen
    chunked=chunked,
  File "D:\program_files\py_virtual_envs\env_myblog\lib\site-packages\urllib3\connectionpool.py", line 387, in _make_request
    conn.request(method, url, **httplib_request_kw)
  File "d:\program_files\python3.7.6\lib\http\client.py", line 1252, in request
    self._send_request(method, url, body, headers, encode_chunked)
  File "d:\program_files\python3.7.6\lib\http\client.py", line 1298, in _send_request
    self.endheaders(body, encode_chunked=encode_chunked)
  File "d:\program_files\python3.7.6\lib\http\client.py", line 1247, in endheaders
    self._send_output(message_body, encode_chunked=encode_chunked)
  File "d:\program_files\python3.7.6\lib\http\client.py", line 1026, in _send_output
    self.send(msg)
  File "d:\program_files\python3.7.6\lib\http\client.py", line 966, in send
    self.connect()
  File "D:\program_files\py_virtual_envs\env_myblog\lib\site-packages\urllib3\connection.py", line 184, in connect
    conn = self._new_conn()
  File "D:\program_files\py_virtual_envs\env_myblog\lib\site-packages\urllib3\connection.py", line 169, in _new_conn
    self, "Failed to establish a new connection: %s" % e
urllib3.exceptions.NewConnectionError: <urllib3.connection.HTTPConnection object at 0x0000020015F12188>: Failed to establish a new connection: [WinError 10061] 由于目标计算机积极拒绝，无法连接。
[2020-04-29 08:57:24,692][MainThread:6288][task_id:elasticsearch][base.py:122][INFO][HEAD http://localhost:9200/ [status:200 request:4.149s]]
[2020-04-29 08:57:24,692][MainThread:6288][task_id:elasticsearch][base.py:122][INFO][HEAD http://localhost:9200/blog [status:200 request:0.000s]]
[2020-04-29 08:57:24,708][MainThread:6288][task_id:elasticsearch][base.py:122][INFO][HEAD http://localhost:9200/ [status:200 request:0.016s]]
[2020-04-29 08:57:24,708][MainThread:6288][task_id:elasticsearch][base.py:122][INFO][HEAD http://localhost:9200/suggestion_db [status:200 request:0.000s]]
[2020-04-29 08:57:25,366][MainThread:11624][task_id:elasticsearch][base.py:122][INFO][HEAD http://localhost:9200/ [status:200 request:0.016s]]
[2020-04-29 08:57:25,366][MainThread:11624][task_id:elasticsearch][base.py:122][INFO][HEAD http://localhost:9200/blog [status:200 request:0.000s]]
[2020-04-29 08:57:25,366][MainThread:11624][task_id:elasticsearch][base.py:122][INFO][HEAD http://localhost:9200/ [status:200 request:0.000s]]
[2020-04-29 08:57:25,382][MainThread:11624][task_id:elasticsearch][base.py:122][INFO][HEAD http://localhost:9200/suggestion_db [status:200 request:0.016s]]
[2020-04-29 08:57:25,633][MainThread:11624][task_id:django.utils.autoreload][autoreload.py:598][INFO][Watching for file changes with StatReloader]
[2020-04-29 09:03:47,574][MainThread:9596][task_id:elasticsearch][base.py:150][WARNING][HEAD http://localhost:9200/ [status:N/A request:4.110s]]
Traceback (most recent call last):
  File "D:\program_files\py_virtual_envs\env_myblog\lib\site-packages\urllib3\connection.py", line 157, in _new_conn
    (self._dns_host, self.port), self.timeout, **extra_kw
  File "D:\program_files\py_virtual_envs\env_myblog\lib\site-packages\urllib3\util\connection.py", line 84, in create_connection
    raise err
  File "D:\program_files\py_virtual_envs\env_myblog\lib\site-packages\urllib3\util\connection.py", line 74, in create_connection
    sock.connect(sa)
ConnectionRefusedError: [WinError 10061] 由于目标计算机积极拒绝，无法连接。

During handling of the above exception, another exception occurred:

Traceback (most recent call last):
  File "D:\program_files\py_virtual_envs\env_myblog\lib\site-packages\elasticsearch\connection\http_urllib3.py", line 242, in perform_request
    method, url, body, retries=Retry(False), headers=request_headers, **kw
  File "D:\program_files\py_virtual_envs\env_myblog\lib\site-packages\urllib3\connectionpool.py", line 720, in urlopen
    method, url, error=e, _pool=self, _stacktrace=sys.exc_info()[2]
  File "D:\program_files\py_virtual_envs\env_myblog\lib\site-packages\urllib3\util\retry.py", line 376, in increment
    raise six.reraise(type(error), error, _stacktrace)
  File "D:\program_files\py_virtual_envs\env_myblog\lib\site-packages\urllib3\packages\six.py", line 735, in reraise
    raise value
  File "D:\program_files\py_virtual_envs\env_myblog\lib\site-packages\urllib3\connectionpool.py", line 672, in urlopen
    chunked=chunked,
  File "D:\program_files\py_virtual_envs\env_myblog\lib\site-packages\urllib3\connectionpool.py", line 387, in _make_request
    conn.request(method, url, **httplib_request_kw)
  File "d:\program_files\python3.7.6\lib\http\client.py", line 1252, in request
    self._send_request(method, url, body, headers, encode_chunked)
  File "d:\program_files\python3.7.6\lib\http\client.py", line 1298, in _send_request
    self.endheaders(body, encode_chunked=encode_chunked)
  File "d:\program_files\python3.7.6\lib\http\client.py", line 1247, in endheaders
    self._send_output(message_body, encode_chunked=encode_chunked)
  File "d:\program_files\python3.7.6\lib\http\client.py", line 1026, in _send_output
    self.send(msg)
  File "d:\program_files\python3.7.6\lib\http\client.py", line 966, in send
    self.connect()
  File "D:\program_files\py_virtual_envs\env_myblog\lib\site-packages\urllib3\connection.py", line 184, in connect
    conn = self._new_conn()
  File "D:\program_files\py_virtual_envs\env_myblog\lib\site-packages\urllib3\connection.py", line 169, in _new_conn
    self, "Failed to establish a new connection: %s" % e
urllib3.exceptions.NewConnectionError: <urllib3.connection.HTTPConnection object at 0x0000017E67A08248>: Failed to establish a new connection: [WinError 10061] 由于目标计算机积极拒绝，无法连接。
[2020-04-29 09:03:51,668][MainThread:9596][task_id:elasticsearch][base.py:150][WARNING][HEAD http://localhost:9200/ [status:N/A request:4.093s]]
Traceback (most recent call last):
  File "D:\program_files\py_virtual_envs\env_myblog\lib\site-packages\urllib3\connection.py", line 157, in _new_conn
    (self._dns_host, self.port), self.timeout, **extra_kw
  File "D:\program_files\py_virtual_envs\env_myblog\lib\site-packages\urllib3\util\connection.py", line 84, in create_connection
    raise err
  File "D:\program_files\py_virtual_envs\env_myblog\lib\site-packages\urllib3\util\connection.py", line 74, in create_connection
    sock.connect(sa)
ConnectionRefusedError: [WinError 10061] 由于目标计算机积极拒绝，无法连接。

During handling of the above exception, another exception occurred:

Traceback (most recent call last):
  File "D:\program_files\py_virtual_envs\env_myblog\lib\site-packages\elasticsearch\connection\http_urllib3.py", line 242, in perform_request
    method, url, body, retries=Retry(False), headers=request_headers, **kw
  File "D:\program_files\py_virtual_envs\env_myblog\lib\site-packages\urllib3\connectionpool.py", line 720, in urlopen
    method, url, error=e, _pool=self, _stacktrace=sys.exc_info()[2]
  File "D:\program_files\py_virtual_envs\env_myblog\lib\site-packages\urllib3\util\retry.py", line 376, in increment
    raise six.reraise(type(error), error, _stacktrace)
  File "D:\program_files\py_virtual_envs\env_myblog\lib\site-packages\urllib3\packages\six.py", line 735, in reraise
    raise value
  File "D:\program_files\py_virtual_envs\env_myblog\lib\site-packages\urllib3\connectionpool.py", line 672, in urlopen
    chunked=chunked,
  File "D:\program_files\py_virtual_envs\env_myblog\lib\site-packages\urllib3\connectionpool.py", line 387, in _make_request
    conn.request(method, url, **httplib_request_kw)
  File "d:\program_files\python3.7.6\lib\http\client.py", line 1252, in request
    self._send_request(method, url, body, headers, encode_chunked)
  File "d:\program_files\python3.7.6\lib\http\client.py", line 1298, in _send_request
    self.endheaders(body, encode_chunked=encode_chunked)
  File "d:\program_files\python3.7.6\lib\http\client.py", line 1247, in endheaders
    self._send_output(message_body, encode_chunked=encode_chunked)
  File "d:\program_files\python3.7.6\lib\http\client.py", line 1026, in _send_output
    self.send(msg)
  File "d:\program_files\python3.7.6\lib\http\client.py", line 966, in send
    self.connect()
  File "D:\program_files\py_virtual_envs\env_myblog\lib\site-packages\urllib3\connection.py", line 184, in connect
    conn = self._new_conn()
  File "D:\program_files\py_virtual_envs\env_myblog\lib\site-packages\urllib3\connection.py", line 169, in _new_conn
    self, "Failed to establish a new connection: %s" % e
urllib3.exceptions.NewConnectionError: <urllib3.connection.HTTPConnection object at 0x0000017E67A22048>: Failed to establish a new connection: [WinError 10061] 由于目标计算机积极拒绝，无法连接。
[2020-04-29 09:03:55,738][MainThread:9596][task_id:elasticsearch][base.py:150][WARNING][HEAD http://localhost:9200/ [status:N/A request:4.071s]]
Traceback (most recent call last):
  File "D:\program_files\py_virtual_envs\env_myblog\lib\site-packages\urllib3\connection.py", line 157, in _new_conn
    (self._dns_host, self.port), self.timeout, **extra_kw
  File "D:\program_files\py_virtual_envs\env_myblog\lib\site-packages\urllib3\util\connection.py", line 84, in create_connection
    raise err
  File "D:\program_files\py_virtual_envs\env_myblog\lib\site-packages\urllib3\util\connection.py", line 74, in create_connection
    sock.connect(sa)
ConnectionRefusedError: [WinError 10061] 由于目标计算机积极拒绝，无法连接。

During handling of the above exception, another exception occurred:

Traceback (most recent call last):
  File "D:\program_files\py_virtual_envs\env_myblog\lib\site-packages\elasticsearch\connection\http_urllib3.py", line 242, in perform_request
    method, url, body, retries=Retry(False), headers=request_headers, **kw
  File "D:\program_files\py_virtual_envs\env_myblog\lib\site-packages\urllib3\connectionpool.py", line 720, in urlopen
    method, url, error=e, _pool=self, _stacktrace=sys.exc_info()[2]
  File "D:\program_files\py_virtual_envs\env_myblog\lib\site-packages\urllib3\util\retry.py", line 376, in increment
    raise six.reraise(type(error), error, _stacktrace)
  File "D:\program_files\py_virtual_envs\env_myblog\lib\site-packages\urllib3\packages\six.py", line 735, in reraise
    raise value
  File "D:\program_files\py_virtual_envs\env_myblog\lib\site-packages\urllib3\connectionpool.py", line 672, in urlopen
    chunked=chunked,
  File "D:\program_files\py_virtual_envs\env_myblog\lib\site-packages\urllib3\connectionpool.py", line 387, in _make_request
    conn.request(method, url, **httplib_request_kw)
  File "d:\program_files\python3.7.6\lib\http\client.py", line 1252, in request
    self._send_request(method, url, body, headers, encode_chunked)
  File "d:\program_files\python3.7.6\lib\http\client.py", line 1298, in _send_request
    self.endheaders(body, encode_chunked=encode_chunked)
  File "d:\program_files\python3.7.6\lib\http\client.py", line 1247, in endheaders
    self._send_output(message_body, encode_chunked=encode_chunked)
  File "d:\program_files\python3.7.6\lib\http\client.py", line 1026, in _send_output
    self.send(msg)
  File "d:\program_files\python3.7.6\lib\http\client.py", line 966, in send
    self.connect()
  File "D:\program_files\py_virtual_envs\env_myblog\lib\site-packages\urllib3\connection.py", line 184, in connect
    conn = self._new_conn()
  File "D:\program_files\py_virtual_envs\env_myblog\lib\site-packages\urllib3\connection.py", line 169, in _new_conn
    self, "Failed to establish a new connection: %s" % e
urllib3.exceptions.NewConnectionError: <urllib3.connection.HTTPConnection object at 0x0000017E67A8B4C8>: Failed to establish a new connection: [WinError 10061] 由于目标计算机积极拒绝，无法连接。
[2020-04-29 09:03:56,333][MainThread:9596][task_id:elasticsearch][base.py:122][INFO][HEAD http://localhost:9200/ [status:200 request:0.595s]]
[2020-04-29 09:03:56,349][MainThread:9596][task_id:elasticsearch][base.py:122][INFO][HEAD http://localhost:9200/blog [status:200 request:0.016s]]
[2020-04-29 09:03:56,365][MainThread:9596][task_id:elasticsearch][base.py:122][INFO][HEAD http://localhost:9200/ [status:200 request:0.016s]]
[2020-04-29 09:03:56,365][MainThread:9596][task_id:elasticsearch][base.py:122][INFO][HEAD http://localhost:9200/suggestion_db [status:200 request:0.000s]]
[2020-04-29 09:03:57,129][MainThread:13076][task_id:elasticsearch][base.py:122][INFO][HEAD http://localhost:9200/ [status:200 request:0.017s]]
[2020-04-29 09:03:57,129][MainThread:13076][task_id:elasticsearch][base.py:122][INFO][HEAD http://localhost:9200/blog [status:200 request:0.000s]]
[2020-04-29 09:03:57,129][MainThread:13076][task_id:elasticsearch][base.py:122][INFO][HEAD http://localhost:9200/ [status:200 request:0.000s]]
[2020-04-29 09:03:57,129][MainThread:13076][task_id:elasticsearch][base.py:122][INFO][HEAD http://localhost:9200/suggestion_db [status:200 request:0.000s]]
[2020-04-29 09:03:57,407][MainThread:13076][task_id:django.utils.autoreload][autoreload.py:598][INFO][Watching for file changes with StatReloader]
[2020-04-29 09:09:06,056][Thread-1:6260][task_id:elasticsearch][base.py:122][INFO][POST http://localhost:9200/blog/_doc/1/_update?filter_path=_shards.successful [status:200 request:0.118s]]
[2020-04-29 09:09:34,040][Thread-1:6260][task_id:elasticsearch][base.py:122][INFO][POST http://localhost:9200/blog/_doc/1/_update?filter_path=_shards.successful [status:200 request:0.016s]]
[2020-04-29 09:09:35,795][Thread-1:6260][task_id:elasticsearch][base.py:122][INFO][POST http://localhost:9200/blog/_doc/1/_update?filter_path=_shards.successful [status:200 request:0.000s]]
[2020-04-29 09:10:00,252][Thread-1:6260][task_id:elasticsearch][base.py:122][INFO][POST http://localhost:9200/blog/_doc/1/_update?filter_path=_shards.successful [status:200 request:0.016s]]
[2020-04-29 09:10:25,602][Thread-1:6260][task_id:elasticsearch][base.py:122][INFO][POST http://localhost:9200/blog/_doc/1/_update?filter_path=_shards.successful [status:200 request:0.031s]]
[2020-04-29 09:10:27,314][Thread-1:6260][task_id:elasticsearch][base.py:122][INFO][POST http://localhost:9200/blog/_doc/1/_update?filter_path=_shards.successful [status:200 request:0.016s]]
[2020-04-29 09:14:39,624][Thread-1:6260][task_id:elasticsearch][base.py:122][INFO][POST http://localhost:9200/blog/_doc/2/_update?filter_path=_shards.successful [status:200 request:0.016s]]
[2020-04-29 09:15:10,624][Thread-1:6260][task_id:elasticsearch][base.py:122][INFO][POST http://localhost:9200/blog/_doc/3/_update?filter_path=_shards.successful [status:200 request:0.016s]]
[2020-04-29 09:16:04,685][Thread-1:6260][task_id:elasticsearch][base.py:122][INFO][POST http://localhost:9200/blog/_doc/3/_update?filter_path=_shards.successful [status:200 request:0.016s]]
[2020-04-29 09:16:46,888][Thread-1:6260][task_id:elasticsearch][base.py:122][INFO][POST http://localhost:9200/blog/_doc/3/_update?filter_path=_shards.successful [status:200 request:0.016s]]
[2020-04-29 09:17:18,687][Thread-1:6260][task_id:elasticsearch][base.py:122][INFO][POST http://localhost:9200/blog/_doc/3/_update?filter_path=_shards.successful [status:200 request:0.016s]]
[2020-04-29 09:17:39,265][Thread-1:6260][task_id:elasticsearch][base.py:122][INFO][POST http://localhost:9200/blog/_doc/3/_update?filter_path=_shards.successful [status:200 request:0.016s]]
[2020-04-29 09:17:46,596][Thread-1:6260][task_id:elasticsearch][base.py:122][INFO][POST http://localhost:9200/blog/_doc/3/_update?filter_path=_shards.successful [status:200 request:0.031s]]
[2020-04-29 09:21:34,538][Thread-1:6260][task_id:elasticsearch][base.py:122][INFO][POST http://localhost:9200/blog/_doc/3/_update?filter_path=_shards.successful [status:200 request:0.016s]]
[2020-04-29 09:23:59,855][Thread-1:6260][task_id:elasticsearch][base.py:122][INFO][POST http://localhost:9200/blog/_doc/3/_update?filter_path=_shards.successful [status:200 request:0.016s]]
[2020-04-29 09:24:28,565][Thread-1:6260][task_id:elasticsearch][base.py:122][INFO][POST http://localhost:9200/blog/_doc/3/_update?filter_path=_shards.successful [status:200 request:0.016s]]
[2020-04-29 09:25:09,927][Thread-1:6260][task_id:elasticsearch][base.py:122][INFO][POST http://localhost:9200/blog/_doc/3/_update?filter_path=_shards.successful [status:200 request:0.016s]]
[2020-04-29 09:28:02,635][Thread-1:6260][task_id:elasticsearch][base.py:122][INFO][POST http://localhost:9200/blog/_doc/4/_update?filter_path=_shards.successful [status:200 request:0.016s]]
[2020-04-29 09:28:26,313][Thread-1:6260][task_id:elasticsearch][base.py:122][INFO][POST http://localhost:9200/blog/_doc/4/_update?filter_path=_shards.successful [status:200 request:0.016s]]
[2020-04-29 09:29:39,984][Thread-1:6260][task_id:elasticsearch][base.py:122][INFO][POST http://localhost:9200/blog/_doc/5/_update?filter_path=_shards.successful [status:200 request:0.016s]]
[2020-04-29 09:29:56,691][Thread-1:6260][task_id:elasticsearch][base.py:122][INFO][POST http://localhost:9200/blog/_doc/5/_update?filter_path=_shards.successful [status:200 request:0.031s]]
[2020-04-29 09:30:33,690][Thread-1:6260][task_id:elasticsearch][base.py:122][INFO][POST http://localhost:9200/blog/_doc/5/_update?filter_path=_shards.successful [status:200 request:0.016s]]
[2020-04-29 09:31:01,714][Thread-1:6260][task_id:elasticsearch][base.py:122][INFO][POST http://localhost:9200/blog/_doc/5/_update?filter_path=_shards.successful [status:200 request:0.016s]]
[2020-04-29 09:32:04,349][Thread-1:6260][task_id:elasticsearch][base.py:122][INFO][POST http://localhost:9200/blog/_doc/5/_update?filter_path=_shards.successful [status:200 request:0.016s]]
[2020-04-29 09:32:55,744][Thread-1:6260][task_id:elasticsearch][base.py:122][INFO][POST http://localhost:9200/blog/_doc/6/_update?filter_path=_shards.successful [status:200 request:0.031s]]
[2020-04-29 09:33:02,867][Thread-1:6260][task_id:elasticsearch][base.py:122][INFO][POST http://localhost:9200/blog/_doc/6/_update?filter_path=_shards.successful [status:200 request:0.031s]]
[2020-04-29 09:35:48,832][Thread-1:6260][task_id:django.request][log.py:228][WARNING][Forbidden: /app01/blog/]
[2020-04-29 09:35:53,716][Thread-1:6260][task_id:django.request][log.py:228][WARNING][Forbidden: /app01/blog/]
[2020-04-29 09:37:54,969][Thread-1:6260][task_id:django.request][log.py:228][WARNING][Forbidden: /app01/blog/]
[2020-04-29 09:38:02,270][Thread-1:6260][task_id:django.request][log.py:228][WARNING][Forbidden: /app01/blog/]
[2020-04-29 09:39:45,295][Thread-1:6260][task_id:django.request][log.py:228][WARNING][Forbidden: /app01/blog/]
[2020-04-29 09:40:47,383][Thread-1:6260][task_id:django.request][log.py:228][WARNING][Forbidden: /app01/blog/]
[2020-04-29 09:48:11,458][Thread-11:14260][task_id:django.request][log.py:228][WARNING][Forbidden: /app01/blog/]
[2020-04-29 09:51:23,858][Thread-11:14260][task_id:django.request][log.py:228][WARNING][Forbidden: /app01/blog/]
[2020-04-29 09:51:42,465][Thread-11:14260][task_id:django.request][log.py:228][WARNING][Forbidden: /app01/blog/]
[2020-04-29 09:52:52,595][Thread-11:14260][task_id:django.request][log.py:228][WARNING][Forbidden: /app01/blog/]
[2020-04-29 09:53:12,185][Thread-11:14260][task_id:django.request][log.py:228][WARNING][Forbidden: /app01/blog/]
[2020-04-29 10:00:35,243][Thread-15:12328][task_id:elasticsearch][base.py:122][INFO][POST http://localhost:9200/blog/_doc/7/_update?filter_path=_shards.successful [status:200 request:0.016s]]
[2020-04-29 10:01:55,088][Thread-15:12328][task_id:elasticsearch][base.py:122][INFO][POST http://localhost:9200/blog/_doc/7/_update?filter_path=_shards.successful [status:200 request:0.024s]]
[2020-04-29 10:02:22,649][Thread-15:12328][task_id:elasticsearch][base.py:122][INFO][POST http://localhost:9200/blog/_doc/8/_update?filter_path=_shards.successful [status:200 request:0.016s]]
[2020-04-29 10:02:53,355][Thread-15:12328][task_id:elasticsearch][base.py:122][INFO][POST http://localhost:9200/blog/_doc/9/_update?filter_path=_shards.successful [status:200 request:0.016s]]
[2020-04-29 10:06:23,344][Thread-15:12328][task_id:django.request][log.py:228][WARNING][Forbidden: /app01/blog/]
[2020-04-29 10:06:37,777][Thread-15:12328][task_id:django.request][log.py:228][WARNING][Forbidden: /app01/blog/]
[2020-04-29 10:07:15,951][Thread-15:12328][task_id:django.request][log.py:228][WARNING][Forbidden: /app01/blog/]
[2020-04-29 10:09:59,505][Thread-15:12328][task_id:django.request][log.py:228][WARNING][Forbidden: /app01/blog/]
[2020-04-29 10:11:40,632][Thread-15:12328][task_id:django.request][log.py:228][WARNING][Forbidden: /app01/blog/]
[2020-04-29 10:17:59,337][Thread-19:5428][task_id:django.request][log.py:228][WARNING][Forbidden: /app01/blog/]
[2020-04-29 10:22:43,566][Thread-19:5428][task_id:elasticsearch][base.py:122][INFO][POST http://localhost:9200/blog/_doc/15/_update?filter_path=_shards.successful [status:200 request:0.024s]]
[2020-04-29 10:25:20,269][Thread-19:5428][task_id:elasticsearch][base.py:122][INFO][POST http://localhost:9200/blog/_doc/10/_update?filter_path=_shards.successful [status:200 request:0.016s]]
[2020-04-29 10:27:31,524][Thread-19:5428][task_id:elasticsearch][base.py:122][INFO][POST http://localhost:9200/blog/_doc/10/_update?filter_path=_shards.successful [status:200 request:0.016s]]
[2020-04-29 10:28:44,266][Thread-19:5428][task_id:elasticsearch][base.py:122][INFO][POST http://localhost:9200/blog/_doc/10/_update?filter_path=_shards.successful [status:200 request:0.016s]]
[2020-04-29 10:29:06,117][Thread-19:5428][task_id:elasticsearch][base.py:122][INFO][POST http://localhost:9200/blog/_doc/10/_update?filter_path=_shards.successful [status:200 request:0.016s]]
[2020-04-29 10:33:22,691][Thread-19:5428][task_id:elasticsearch][base.py:122][INFO][POST http://localhost:9200/blog/_doc/11/_update?filter_path=_shards.successful [status:200 request:0.016s]]
[2020-04-29 10:33:36,283][Thread-19:5428][task_id:elasticsearch][base.py:122][INFO][POST http://localhost:9200/blog/_doc/11/_update?filter_path=_shards.successful [status:200 request:0.016s]]
[2020-04-29 10:33:50,895][Thread-19:5428][task_id:elasticsearch][base.py:122][INFO][POST http://localhost:9200/blog/_doc/11/_update?filter_path=_shards.successful [status:200 request:0.024s]]
[2020-04-29 10:42:05,055][Thread-19:5428][task_id:django.request][log.py:228][WARNING][Forbidden: /app01/blog/]
[2020-04-29 10:53:34,291][Thread-26:13132][task_id:elasticsearch][base.py:122][INFO][POST http://localhost:9200/blog/_doc/17/_update?filter_path=_shards.successful [status:200 request:0.016s]]
[2020-04-29 11:08:21,253][Thread-27:6100][task_id:elasticsearch][base.py:122][INFO][POST http://localhost:9200/blog/_doc/12/_update?filter_path=_shards.successful [status:200 request:0.016s]]
[2020-04-29 11:08:55,969][Thread-27:6100][task_id:elasticsearch][base.py:122][INFO][POST http://localhost:9200/blog/_doc/12/_update?filter_path=_shards.successful [status:200 request:0.016s]]
[2020-04-29 11:12:45,021][MainThread:13076][task_id:django.utils.autoreload][autoreload.py:222][INFO][D:\python_files\PythonProject\Site\Blog\views.py changed, reloading.]
[2020-04-29 11:12:45,543][MainThread:12384][task_id:elasticsearch][base.py:122][INFO][HEAD http://localhost:9200/ [status:200 request:0.031s]]
[2020-04-29 11:12:45,543][MainThread:12384][task_id:elasticsearch][base.py:122][INFO][HEAD http://localhost:9200/blog [status:200 request:0.000s]]
[2020-04-29 11:12:45,543][MainThread:12384][task_id:elasticsearch][base.py:122][INFO][HEAD http://localhost:9200/ [status:200 request:0.000s]]
[2020-04-29 11:12:45,543][MainThread:12384][task_id:elasticsearch][base.py:122][INFO][HEAD http://localhost:9200/suggestion_db [status:200 request:0.000s]]
[2020-04-29 11:12:45,836][MainThread:12384][task_id:django.utils.autoreload][autoreload.py:598][INFO][Watching for file changes with StatReloader]
[2020-04-29 11:17:14,180][MainThread:12384][task_id:django.utils.autoreload][autoreload.py:222][INFO][D:\python_files\PythonProject\Site\utils\es.py changed, reloading.]
[2020-04-29 11:17:14,947][MainThread:14800][task_id:django.utils.autoreload][autoreload.py:598][INFO][Watching for file changes with StatReloader]
[2020-04-29 11:18:55,572][MainThread:14800][task_id:django.utils.autoreload][autoreload.py:222][INFO][D:\python_files\PythonProject\Site\utils\es.py changed, reloading.]
[2020-04-29 11:18:56,061][MainThread:9188][task_id:elasticsearch][base.py:122][INFO][HEAD http://localhost:9200/ [status:200 request:0.024s]]
[2020-04-29 11:18:56,061][MainThread:9188][task_id:elasticsearch][base.py:122][INFO][HEAD http://localhost:9200/ [status:200 request:0.000s]]
[2020-04-29 11:18:56,061][MainThread:9188][task_id:elasticsearch][base.py:122][INFO][HEAD http://localhost:9200/blog [status:200 request:0.000s]]
[2020-04-29 11:18:56,069][MainThread:9188][task_id:elasticsearch][base.py:122][INFO][HEAD http://localhost:9200/ [status:200 request:0.008s]]
[2020-04-29 11:18:56,069][MainThread:9188][task_id:elasticsearch][base.py:122][INFO][HEAD http://localhost:9200/suggestion_db [status:200 request:0.000s]]
[2020-04-29 11:18:56,261][MainThread:9188][task_id:django.utils.autoreload][autoreload.py:598][INFO][Watching for file changes with StatReloader]
[2020-04-29 11:19:25,028][Thread-1:2528][task_id:django.request][log.py:228][WARNING][Forbidden: /app01/blog/]
[2020-04-29 11:19:32,291][Thread-1:2528][task_id:django.request][log.py:228][WARNING][Forbidden: /app01/blog/]
[2020-04-29 11:27:44,053][Thread-3:9920][task_id:elasticsearch][base.py:122][INFO][POST http://localhost:9200/blog/_doc/13/_update?filter_path=_shards.successful [status:200 request:0.016s]]
[2020-04-29 12:07:32,414][Thread-5:14000][task_id:django.request][log.py:228][WARNING][Forbidden: /app01/blog/]
[2020-04-29 12:26:00,194][Thread-10:15416][task_id:django.request][log.py:228][WARNING][Forbidden: /app01/blog/]
[2020-04-29 12:42:47,423][Thread-14:14036][task_id:elasticsearch][base.py:122][INFO][POST http://localhost:9200/blog/_doc/14/_update?filter_path=_shards.successful [status:200 request:0.017s]]
[2020-04-29 12:44:18,307][MainThread:9188][task_id:django.utils.autoreload][autoreload.py:222][INFO][D:\python_files\PythonProject\Site\Blog\views.py changed, reloading.]
[2020-04-29 12:44:18,845][MainThread:15072][task_id:elasticsearch][base.py:122][INFO][HEAD http://localhost:9200/ [status:200 request:0.016s]]
[2020-04-29 12:44:18,846][MainThread:15072][task_id:elasticsearch][base.py:122][INFO][HEAD http://localhost:9200/ [status:200 request:0.001s]]
[2020-04-29 12:44:18,849][MainThread:15072][task_id:elasticsearch][base.py:122][INFO][HEAD http://localhost:9200/blog [status:200 request:0.002s]]
[2020-04-29 12:44:18,851][MainThread:15072][task_id:elasticsearch][base.py:122][INFO][HEAD http://localhost:9200/ [status:200 request:0.002s]]
[2020-04-29 12:44:18,853][MainThread:15072][task_id:elasticsearch][base.py:122][INFO][HEAD http://localhost:9200/suggestion_db [status:200 request:0.002s]]
[2020-04-29 12:44:19,063][MainThread:15072][task_id:django.utils.autoreload][autoreload.py:598][INFO][Watching for file changes with StatReloader]
[2020-04-29 12:54:21,317][MainThread:13208][task_id:elasticsearch][base.py:150][WARNING][HEAD http://localhost:9200/ [status:N/A request:4.030s]]
Traceback (most recent call last):
  File "D:\program_files\py_virtual_envs\env_myblog\lib\site-packages\urllib3\connection.py", line 157, in _new_conn
    (self._dns_host, self.port), self.timeout, **extra_kw
  File "D:\program_files\py_virtual_envs\env_myblog\lib\site-packages\urllib3\util\connection.py", line 84, in create_connection
    raise err
  File "D:\program_files\py_virtual_envs\env_myblog\lib\site-packages\urllib3\util\connection.py", line 74, in create_connection
    sock.connect(sa)
ConnectionRefusedError: [WinError 10061] 由于目标计算机积极拒绝，无法连接。

During handling of the above exception, another exception occurred:

Traceback (most recent call last):
  File "D:\program_files\py_virtual_envs\env_myblog\lib\site-packages\elasticsearch\connection\http_urllib3.py", line 242, in perform_request
    method, url, body, retries=Retry(False), headers=request_headers, **kw
  File "D:\program_files\py_virtual_envs\env_myblog\lib\site-packages\urllib3\connectionpool.py", line 720, in urlopen
    method, url, error=e, _pool=self, _stacktrace=sys.exc_info()[2]
  File "D:\program_files\py_virtual_envs\env_myblog\lib\site-packages\urllib3\util\retry.py", line 376, in increment
    raise six.reraise(type(error), error, _stacktrace)
  File "D:\program_files\py_virtual_envs\env_myblog\lib\site-packages\urllib3\packages\six.py", line 735, in reraise
    raise value
  File "D:\program_files\py_virtual_envs\env_myblog\lib\site-packages\urllib3\connectionpool.py", line 672, in urlopen
    chunked=chunked,
  File "D:\program_files\py_virtual_envs\env_myblog\lib\site-packages\urllib3\connectionpool.py", line 387, in _make_request
    conn.request(method, url, **httplib_request_kw)
  File "d:\program_files\python3.7.6\lib\http\client.py", line 1252, in request
    self._send_request(method, url, body, headers, encode_chunked)
  File "d:\program_files\python3.7.6\lib\http\client.py", line 1298, in _send_request
    self.endheaders(body, encode_chunked=encode_chunked)
  File "d:\program_files\python3.7.6\lib\http\client.py", line 1247, in endheaders
    self._send_output(message_body, encode_chunked=encode_chunked)
  File "d:\program_files\python3.7.6\lib\http\client.py", line 1026, in _send_output
    self.send(msg)
  File "d:\program_files\python3.7.6\lib\http\client.py", line 966, in send
    self.connect()
  File "D:\program_files\py_virtual_envs\env_myblog\lib\site-packages\urllib3\connection.py", line 184, in connect
    conn = self._new_conn()
  File "D:\program_files\py_virtual_envs\env_myblog\lib\site-packages\urllib3\connection.py", line 169, in _new_conn
    self, "Failed to establish a new connection: %s" % e
urllib3.exceptions.NewConnectionError: <urllib3.connection.HTTPConnection object at 0x00000179D6D829C8>: Failed to establish a new connection: [WinError 10061] 由于目标计算机积极拒绝，无法连接。
[2020-04-29 12:54:25,349][MainThread:13208][task_id:elasticsearch][base.py:150][WARNING][HEAD http://localhost:9200/ [status:N/A request:4.027s]]
Traceback (most recent call last):
  File "D:\program_files\py_virtual_envs\env_myblog\lib\site-packages\urllib3\connection.py", line 157, in _new_conn
    (self._dns_host, self.port), self.timeout, **extra_kw
  File "D:\program_files\py_virtual_envs\env_myblog\lib\site-packages\urllib3\util\connection.py", line 84, in create_connection
    raise err
  File "D:\program_files\py_virtual_envs\env_myblog\lib\site-packages\urllib3\util\connection.py", line 74, in create_connection
    sock.connect(sa)
ConnectionRefusedError: [WinError 10061] 由于目标计算机积极拒绝，无法连接。

During handling of the above exception, another exception occurred:

Traceback (most recent call last):
  File "D:\program_files\py_virtual_envs\env_myblog\lib\site-packages\elasticsearch\connection\http_urllib3.py", line 242, in perform_request
    method, url, body, retries=Retry(False), headers=request_headers, **kw
  File "D:\program_files\py_virtual_envs\env_myblog\lib\site-packages\urllib3\connectionpool.py", line 720, in urlopen
    method, url, error=e, _pool=self, _stacktrace=sys.exc_info()[2]
  File "D:\program_files\py_virtual_envs\env_myblog\lib\site-packages\urllib3\util\retry.py", line 376, in increment
    raise six.reraise(type(error), error, _stacktrace)
  File "D:\program_files\py_virtual_envs\env_myblog\lib\site-packages\urllib3\packages\six.py", line 735, in reraise
    raise value
  File "D:\program_files\py_virtual_envs\env_myblog\lib\site-packages\urllib3\connectionpool.py", line 672, in urlopen
    chunked=chunked,
  File "D:\program_files\py_virtual_envs\env_myblog\lib\site-packages\urllib3\connectionpool.py", line 387, in _make_request
    conn.request(method, url, **httplib_request_kw)
  File "d:\program_files\python3.7.6\lib\http\client.py", line 1252, in request
    self._send_request(method, url, body, headers, encode_chunked)
  File "d:\program_files\python3.7.6\lib\http\client.py", line 1298, in _send_request
    self.endheaders(body, encode_chunked=encode_chunked)
  File "d:\program_files\python3.7.6\lib\http\client.py", line 1247, in endheaders
    self._send_output(message_body, encode_chunked=encode_chunked)
  File "d:\program_files\python3.7.6\lib\http\client.py", line 1026, in _send_output
    self.send(msg)
  File "d:\program_files\python3.7.6\lib\http\client.py", line 966, in send
    self.connect()
  File "D:\program_files\py_virtual_envs\env_myblog\lib\site-packages\urllib3\connection.py", line 184, in connect
    conn = self._new_conn()
  File "D:\program_files\py_virtual_envs\env_myblog\lib\site-packages\urllib3\connection.py", line 169, in _new_conn
    self, "Failed to establish a new connection: %s" % e
urllib3.exceptions.NewConnectionError: <urllib3.connection.HTTPConnection object at 0x00000179D6D9C848>: Failed to establish a new connection: [WinError 10061] 由于目标计算机积极拒绝，无法连接。
[2020-04-29 12:54:29,368][MainThread:13208][task_id:elasticsearch][base.py:150][WARNING][HEAD http://localhost:9200/ [status:N/A request:4.017s]]
Traceback (most recent call last):
  File "D:\program_files\py_virtual_envs\env_myblog\lib\site-packages\urllib3\connection.py", line 157, in _new_conn
    (self._dns_host, self.port), self.timeout, **extra_kw
  File "D:\program_files\py_virtual_envs\env_myblog\lib\site-packages\urllib3\util\connection.py", line 84, in create_connection
    raise err
  File "D:\program_files\py_virtual_envs\env_myblog\lib\site-packages\urllib3\util\connection.py", line 74, in create_connection
    sock.connect(sa)
ConnectionRefusedError: [WinError 10061] 由于目标计算机积极拒绝，无法连接。

During handling of the above exception, another exception occurred:

Traceback (most recent call last):
  File "D:\program_files\py_virtual_envs\env_myblog\lib\site-packages\elasticsearch\connection\http_urllib3.py", line 242, in perform_request
    method, url, body, retries=Retry(False), headers=request_headers, **kw
  File "D:\program_files\py_virtual_envs\env_myblog\lib\site-packages\urllib3\connectionpool.py", line 720, in urlopen
    method, url, error=e, _pool=self, _stacktrace=sys.exc_info()[2]
  File "D:\program_files\py_virtual_envs\env_myblog\lib\site-packages\urllib3\util\retry.py", line 376, in increment
    raise six.reraise(type(error), error, _stacktrace)
  File "D:\program_files\py_virtual_envs\env_myblog\lib\site-packages\urllib3\packages\six.py", line 735, in reraise
    raise value
  File "D:\program_files\py_virtual_envs\env_myblog\lib\site-packages\urllib3\connectionpool.py", line 672, in urlopen
    chunked=chunked,
  File "D:\program_files\py_virtual_envs\env_myblog\lib\site-packages\urllib3\connectionpool.py", line 387, in _make_request
    conn.request(method, url, **httplib_request_kw)
  File "d:\program_files\python3.7.6\lib\http\client.py", line 1252, in request
    self._send_request(method, url, body, headers, encode_chunked)
  File "d:\program_files\python3.7.6\lib\http\client.py", line 1298, in _send_request
    self.endheaders(body, encode_chunked=encode_chunked)
  File "d:\program_files\python3.7.6\lib\http\client.py", line 1247, in endheaders
    self._send_output(message_body, encode_chunked=encode_chunked)
  File "d:\program_files\python3.7.6\lib\http\client.py", line 1026, in _send_output
    self.send(msg)
  File "d:\program_files\python3.7.6\lib\http\client.py", line 966, in send
    self.connect()
  File "D:\program_files\py_virtual_envs\env_myblog\lib\site-packages\urllib3\connection.py", line 184, in connect
    conn = self._new_conn()
  File "D:\program_files\py_virtual_envs\env_myblog\lib\site-packages\urllib3\connection.py", line 169, in _new_conn
    self, "Failed to establish a new connection: %s" % e
urllib3.exceptions.NewConnectionError: <urllib3.connection.HTTPConnection object at 0x00000179D6E01CC8>: Failed to establish a new connection: [WinError 10061] 由于目标计算机积极拒绝，无法连接。
[2020-04-29 12:54:33,398][MainThread:13208][task_id:elasticsearch][base.py:150][WARNING][HEAD http://localhost:9200/ [status:N/A request:4.029s]]
Traceback (most recent call last):
  File "D:\program_files\py_virtual_envs\env_myblog\lib\site-packages\urllib3\connection.py", line 157, in _new_conn
    (self._dns_host, self.port), self.timeout, **extra_kw
  File "D:\program_files\py_virtual_envs\env_myblog\lib\site-packages\urllib3\util\connection.py", line 84, in create_connection
    raise err
  File "D:\program_files\py_virtual_envs\env_myblog\lib\site-packages\urllib3\util\connection.py", line 74, in create_connection
    sock.connect(sa)
ConnectionRefusedError: [WinError 10061] 由于目标计算机积极拒绝，无法连接。

During handling of the above exception, another exception occurred:

Traceback (most recent call last):
  File "D:\program_files\py_virtual_envs\env_myblog\lib\site-packages\elasticsearch\connection\http_urllib3.py", line 242, in perform_request
    method, url, body, retries=Retry(False), headers=request_headers, **kw
  File "D:\program_files\py_virtual_envs\env_myblog\lib\site-packages\urllib3\connectionpool.py", line 720, in urlopen
    method, url, error=e, _pool=self, _stacktrace=sys.exc_info()[2]
  File "D:\program_files\py_virtual_envs\env_myblog\lib\site-packages\urllib3\util\retry.py", line 376, in increment
    raise six.reraise(type(error), error, _stacktrace)
  File "D:\program_files\py_virtual_envs\env_myblog\lib\site-packages\urllib3\packages\six.py", line 735, in reraise
    raise value
  File "D:\program_files\py_virtual_envs\env_myblog\lib\site-packages\urllib3\connectionpool.py", line 672, in urlopen
    chunked=chunked,
  File "D:\program_files\py_virtual_envs\env_myblog\lib\site-packages\urllib3\connectionpool.py", line 387, in _make_request
    conn.request(method, url, **httplib_request_kw)
  File "d:\program_files\python3.7.6\lib\http\client.py", line 1252, in request
    self._send_request(method, url, body, headers, encode_chunked)
  File "d:\program_files\python3.7.6\lib\http\client.py", line 1298, in _send_request
    self.endheaders(body, encode_chunked=encode_chunked)
  File "d:\program_files\python3.7.6\lib\http\client.py", line 1247, in endheaders
    self._send_output(message_body, encode_chunked=encode_chunked)
  File "d:\program_files\python3.7.6\lib\http\client.py", line 1026, in _send_output
    self.send(msg)
  File "d:\program_files\python3.7.6\lib\http\client.py", line 966, in send
    self.connect()
  File "D:\program_files\py_virtual_envs\env_myblog\lib\site-packages\urllib3\connection.py", line 184, in connect
    conn = self._new_conn()
  File "D:\program_files\py_virtual_envs\env_myblog\lib\site-packages\urllib3\connection.py", line 169, in _new_conn
    self, "Failed to establish a new connection: %s" % e
urllib3.exceptions.NewConnectionError: <urllib3.connection.HTTPConnection object at 0x00000179D6E0B488>: Failed to establish a new connection: [WinError 10061] 由于目标计算机积极拒绝，无法连接。
[2020-04-29 12:54:37,428][MainThread:13208][task_id:elasticsearch][base.py:150][WARNING][HEAD http://localhost:9200/ [status:N/A request:4.025s]]
Traceback (most recent call last):
  File "D:\program_files\py_virtual_envs\env_myblog\lib\site-packages\urllib3\connection.py", line 157, in _new_conn
    (self._dns_host, self.port), self.timeout, **extra_kw
  File "D:\program_files\py_virtual_envs\env_myblog\lib\site-packages\urllib3\util\connection.py", line 84, in create_connection
    raise err
  File "D:\program_files\py_virtual_envs\env_myblog\lib\site-packages\urllib3\util\connection.py", line 74, in create_connection
    sock.connect(sa)
ConnectionRefusedError: [WinError 10061] 由于目标计算机积极拒绝，无法连接。

During handling of the above exception, another exception occurred:

Traceback (most recent call last):
  File "D:\program_files\py_virtual_envs\env_myblog\lib\site-packages\elasticsearch\connection\http_urllib3.py", line 242, in perform_request
    method, url, body, retries=Retry(False), headers=request_headers, **kw
  File "D:\program_files\py_virtual_envs\env_myblog\lib\site-packages\urllib3\connectionpool.py", line 720, in urlopen
    method, url, error=e, _pool=self, _stacktrace=sys.exc_info()[2]
  File "D:\program_files\py_virtual_envs\env_myblog\lib\site-packages\urllib3\util\retry.py", line 376, in increment
    raise six.reraise(type(error), error, _stacktrace)
  File "D:\program_files\py_virtual_envs\env_myblog\lib\site-packages\urllib3\packages\six.py", line 735, in reraise
    raise value
  File "D:\program_files\py_virtual_envs\env_myblog\lib\site-packages\urllib3\connectionpool.py", line 672, in urlopen
    chunked=chunked,
  File "D:\program_files\py_virtual_envs\env_myblog\lib\site-packages\urllib3\connectionpool.py", line 387, in _make_request
    conn.request(method, url, **httplib_request_kw)
  File "d:\program_files\python3.7.6\lib\http\client.py", line 1252, in request
    self._send_request(method, url, body, headers, encode_chunked)
  File "d:\program_files\python3.7.6\lib\http\client.py", line 1298, in _send_request
    self.endheaders(body, encode_chunked=encode_chunked)
  File "d:\program_files\python3.7.6\lib\http\client.py", line 1247, in endheaders
    self._send_output(message_body, encode_chunked=encode_chunked)
  File "d:\program_files\python3.7.6\lib\http\client.py", line 1026, in _send_output
    self.send(msg)
  File "d:\program_files\python3.7.6\lib\http\client.py", line 966, in send
    self.connect()
  File "D:\program_files\py_virtual_envs\env_myblog\lib\site-packages\urllib3\connection.py", line 184, in connect
    conn = self._new_conn()
  File "D:\program_files\py_virtual_envs\env_myblog\lib\site-packages\urllib3\connection.py", line 169, in _new_conn
    self, "Failed to establish a new connection: %s" % e
urllib3.exceptions.NewConnectionError: <urllib3.connection.HTTPConnection object at 0x00000179D6E0BE48>: Failed to establish a new connection: [WinError 10061] 由于目标计算机积极拒绝，无法连接。
[2020-04-29 12:54:41,436][MainThread:13208][task_id:elasticsearch][base.py:150][WARNING][HEAD http://localhost:9200/ [status:N/A request:4.007s]]
Traceback (most recent call last):
  File "D:\program_files\py_virtual_envs\env_myblog\lib\site-packages\urllib3\connection.py", line 157, in _new_conn
    (self._dns_host, self.port), self.timeout, **extra_kw
  File "D:\program_files\py_virtual_envs\env_myblog\lib\site-packages\urllib3\util\connection.py", line 84, in create_connection
    raise err
  File "D:\program_files\py_virtual_envs\env_myblog\lib\site-packages\urllib3\util\connection.py", line 74, in create_connection
    sock.connect(sa)
ConnectionRefusedError: [WinError 10061] 由于目标计算机积极拒绝，无法连接。

During handling of the above exception, another exception occurred:

Traceback (most recent call last):
  File "D:\program_files\py_virtual_envs\env_myblog\lib\site-packages\elasticsearch\connection\http_urllib3.py", line 242, in perform_request
    method, url, body, retries=Retry(False), headers=request_headers, **kw
  File "D:\program_files\py_virtual_envs\env_myblog\lib\site-packages\urllib3\connectionpool.py", line 720, in urlopen
    method, url, error=e, _pool=self, _stacktrace=sys.exc_info()[2]
  File "D:\program_files\py_virtual_envs\env_myblog\lib\site-packages\urllib3\util\retry.py", line 376, in increment
    raise six.reraise(type(error), error, _stacktrace)
  File "D:\program_files\py_virtual_envs\env_myblog\lib\site-packages\urllib3\packages\six.py", line 735, in reraise
    raise value
  File "D:\program_files\py_virtual_envs\env_myblog\lib\site-packages\urllib3\connectionpool.py", line 672, in urlopen
    chunked=chunked,
  File "D:\program_files\py_virtual_envs\env_myblog\lib\site-packages\urllib3\connectionpool.py", line 387, in _make_request
    conn.request(method, url, **httplib_request_kw)
  File "d:\program_files\python3.7.6\lib\http\client.py", line 1252, in request
    self._send_request(method, url, body, headers, encode_chunked)
  File "d:\program_files\python3.7.6\lib\http\client.py", line 1298, in _send_request
    self.endheaders(body, encode_chunked=encode_chunked)
  File "d:\program_files\python3.7.6\lib\http\client.py", line 1247, in endheaders
    self._send_output(message_body, encode_chunked=encode_chunked)
  File "d:\program_files\python3.7.6\lib\http\client.py", line 1026, in _send_output
    self.send(msg)
  File "d:\program_files\python3.7.6\lib\http\client.py", line 966, in send
    self.connect()
  File "D:\program_files\py_virtual_envs\env_myblog\lib\site-packages\urllib3\connection.py", line 184, in connect
    conn = self._new_conn()
  File "D:\program_files\py_virtual_envs\env_myblog\lib\site-packages\urllib3\connection.py", line 169, in _new_conn
    self, "Failed to establish a new connection: %s" % e
urllib3.exceptions.NewConnectionError: <urllib3.connection.HTTPConnection object at 0x00000179D6E11548>: Failed to establish a new connection: [WinError 10061] 由于目标计算机积极拒绝，无法连接。
[2020-04-29 12:54:49,071][MainThread:3208][task_id:elasticsearch][base.py:150][WARNING][HEAD http://localhost:9200/ [status:N/A request:4.031s]]
Traceback (most recent call last):
  File "D:\program_files\py_virtual_envs\env_myblog\lib\site-packages\urllib3\connection.py", line 157, in _new_conn
    (self._dns_host, self.port), self.timeout, **extra_kw
  File "D:\program_files\py_virtual_envs\env_myblog\lib\site-packages\urllib3\util\connection.py", line 84, in create_connection
    raise err
  File "D:\program_files\py_virtual_envs\env_myblog\lib\site-packages\urllib3\util\connection.py", line 74, in create_connection
    sock.connect(sa)
ConnectionRefusedError: [WinError 10061] 由于目标计算机积极拒绝，无法连接。

During handling of the above exception, another exception occurred:

Traceback (most recent call last):
  File "D:\program_files\py_virtual_envs\env_myblog\lib\site-packages\elasticsearch\connection\http_urllib3.py", line 242, in perform_request
    method, url, body, retries=Retry(False), headers=request_headers, **kw
  File "D:\program_files\py_virtual_envs\env_myblog\lib\site-packages\urllib3\connectionpool.py", line 720, in urlopen
    method, url, error=e, _pool=self, _stacktrace=sys.exc_info()[2]
  File "D:\program_files\py_virtual_envs\env_myblog\lib\site-packages\urllib3\util\retry.py", line 376, in increment
    raise six.reraise(type(error), error, _stacktrace)
  File "D:\program_files\py_virtual_envs\env_myblog\lib\site-packages\urllib3\packages\six.py", line 735, in reraise
    raise value
  File "D:\program_files\py_virtual_envs\env_myblog\lib\site-packages\urllib3\connectionpool.py", line 672, in urlopen
    chunked=chunked,
  File "D:\program_files\py_virtual_envs\env_myblog\lib\site-packages\urllib3\connectionpool.py", line 387, in _make_request
    conn.request(method, url, **httplib_request_kw)
  File "d:\program_files\python3.7.6\lib\http\client.py", line 1252, in request
    self._send_request(method, url, body, headers, encode_chunked)
  File "d:\program_files\python3.7.6\lib\http\client.py", line 1298, in _send_request
    self.endheaders(body, encode_chunked=encode_chunked)
  File "d:\program_files\python3.7.6\lib\http\client.py", line 1247, in endheaders
    self._send_output(message_body, encode_chunked=encode_chunked)
  File "d:\program_files\python3.7.6\lib\http\client.py", line 1026, in _send_output
    self.send(msg)
  File "d:\program_files\python3.7.6\lib\http\client.py", line 966, in send
    self.connect()
  File "D:\program_files\py_virtual_envs\env_myblog\lib\site-packages\urllib3\connection.py", line 184, in connect
    conn = self._new_conn()
  File "D:\program_files\py_virtual_envs\env_myblog\lib\site-packages\urllib3\connection.py", line 169, in _new_conn
    self, "Failed to establish a new connection: %s" % e
urllib3.exceptions.NewConnectionError: <urllib3.connection.HTTPConnection object at 0x00000156551E3848>: Failed to establish a new connection: [WinError 10061] 由于目标计算机积极拒绝，无法连接。
[2020-04-29 12:54:53,092][MainThread:3208][task_id:elasticsearch][base.py:150][WARNING][HEAD http://localhost:9200/ [status:N/A request:4.019s]]
Traceback (most recent call last):
  File "D:\program_files\py_virtual_envs\env_myblog\lib\site-packages\urllib3\connection.py", line 157, in _new_conn
    (self._dns_host, self.port), self.timeout, **extra_kw
  File "D:\program_files\py_virtual_envs\env_myblog\lib\site-packages\urllib3\util\connection.py", line 84, in create_connection
    raise err
  File "D:\program_files\py_virtual_envs\env_myblog\lib\site-packages\urllib3\util\connection.py", line 74, in create_connection
    sock.connect(sa)
ConnectionRefusedError: [WinError 10061] 由于目标计算机积极拒绝，无法连接。

During handling of the above exception, another exception occurred:

Traceback (most recent call last):
  File "D:\program_files\py_virtual_envs\env_myblog\lib\site-packages\elasticsearch\connection\http_urllib3.py", line 242, in perform_request
    method, url, body, retries=Retry(False), headers=request_headers, **kw
  File "D:\program_files\py_virtual_envs\env_myblog\lib\site-packages\urllib3\connectionpool.py", line 720, in urlopen
    method, url, error=e, _pool=self, _stacktrace=sys.exc_info()[2]
  File "D:\program_files\py_virtual_envs\env_myblog\lib\site-packages\urllib3\util\retry.py", line 376, in increment
    raise six.reraise(type(error), error, _stacktrace)
  File "D:\program_files\py_virtual_envs\env_myblog\lib\site-packages\urllib3\packages\six.py", line 735, in reraise
    raise value
  File "D:\program_files\py_virtual_envs\env_myblog\lib\site-packages\urllib3\connectionpool.py", line 672, in urlopen
    chunked=chunked,
  File "D:\program_files\py_virtual_envs\env_myblog\lib\site-packages\urllib3\connectionpool.py", line 387, in _make_request
    conn.request(method, url, **httplib_request_kw)
  File "d:\program_files\python3.7.6\lib\http\client.py", line 1252, in request
    self._send_request(method, url, body, headers, encode_chunked)
  File "d:\program_files\python3.7.6\lib\http\client.py", line 1298, in _send_request
    self.endheaders(body, encode_chunked=encode_chunked)
  File "d:\program_files\python3.7.6\lib\http\client.py", line 1247, in endheaders
    self._send_output(message_body, encode_chunked=encode_chunked)
  File "d:\program_files\python3.7.6\lib\http\client.py", line 1026, in _send_output
    self.send(msg)
  File "d:\program_files\python3.7.6\lib\http\client.py", line 966, in send
    self.connect()
  File "D:\program_files\py_virtual_envs\env_myblog\lib\site-packages\urllib3\connection.py", line 184, in connect
    conn = self._new_conn()
  File "D:\program_files\py_virtual_envs\env_myblog\lib\site-packages\urllib3\connection.py", line 169, in _new_conn
    self, "Failed to establish a new connection: %s" % e
urllib3.exceptions.NewConnectionError: <urllib3.connection.HTTPConnection object at 0x00000156551FD6C8>: Failed to establish a new connection: [WinError 10061] 由于目标计算机积极拒绝，无法连接。
[2020-04-29 12:54:57,112][MainThread:3208][task_id:elasticsearch][base.py:150][WARNING][HEAD http://localhost:9200/ [status:N/A request:4.018s]]
Traceback (most recent call last):
  File "D:\program_files\py_virtual_envs\env_myblog\lib\site-packages\urllib3\connection.py", line 157, in _new_conn
    (self._dns_host, self.port), self.timeout, **extra_kw
  File "D:\program_files\py_virtual_envs\env_myblog\lib\site-packages\urllib3\util\connection.py", line 84, in create_connection
    raise err
  File "D:\program_files\py_virtual_envs\env_myblog\lib\site-packages\urllib3\util\connection.py", line 74, in create_connection
    sock.connect(sa)
ConnectionRefusedError: [WinError 10061] 由于目标计算机积极拒绝，无法连接。

During handling of the above exception, another exception occurred:

Traceback (most recent call last):
  File "D:\program_files\py_virtual_envs\env_myblog\lib\site-packages\elasticsearch\connection\http_urllib3.py", line 242, in perform_request
    method, url, body, retries=Retry(False), headers=request_headers, **kw
  File "D:\program_files\py_virtual_envs\env_myblog\lib\site-packages\urllib3\connectionpool.py", line 720, in urlopen
    method, url, error=e, _pool=self, _stacktrace=sys.exc_info()[2]
  File "D:\program_files\py_virtual_envs\env_myblog\lib\site-packages\urllib3\util\retry.py", line 376, in increment
    raise six.reraise(type(error), error, _stacktrace)
  File "D:\program_files\py_virtual_envs\env_myblog\lib\site-packages\urllib3\packages\six.py", line 735, in reraise
    raise value
  File "D:\program_files\py_virtual_envs\env_myblog\lib\site-packages\urllib3\connectionpool.py", line 672, in urlopen
    chunked=chunked,
  File "D:\program_files\py_virtual_envs\env_myblog\lib\site-packages\urllib3\connectionpool.py", line 387, in _make_request
    conn.request(method, url, **httplib_request_kw)
  File "d:\program_files\python3.7.6\lib\http\client.py", line 1252, in request
    self._send_request(method, url, body, headers, encode_chunked)
  File "d:\program_files\python3.7.6\lib\http\client.py", line 1298, in _send_request
    self.endheaders(body, encode_chunked=encode_chunked)
  File "d:\program_files\python3.7.6\lib\http\client.py", line 1247, in endheaders
    self._send_output(message_body, encode_chunked=encode_chunked)
  File "d:\program_files\python3.7.6\lib\http\client.py", line 1026, in _send_output
    self.send(msg)
  File "d:\program_files\python3.7.6\lib\http\client.py", line 966, in send
    self.connect()
  File "D:\program_files\py_virtual_envs\env_myblog\lib\site-packages\urllib3\connection.py", line 184, in connect
    conn = self._new_conn()
  File "D:\program_files\py_virtual_envs\env_myblog\lib\site-packages\urllib3\connection.py", line 169, in _new_conn
    self, "Failed to establish a new connection: %s" % e
urllib3.exceptions.NewConnectionError: <urllib3.connection.HTTPConnection object at 0x0000015655264B48>: Failed to establish a new connection: [WinError 10061] 由于目标计算机积极拒绝，无法连接。
[2020-04-29 12:55:06,808][MainThread:4512][task_id:elasticsearch][base.py:150][WARNING][HEAD http://localhost:9200/ [status:N/A request:4.030s]]
Traceback (most recent call last):
  File "D:\program_files\py_virtual_envs\env_myblog\lib\site-packages\urllib3\connection.py", line 157, in _new_conn
    (self._dns_host, self.port), self.timeout, **extra_kw
  File "D:\program_files\py_virtual_envs\env_myblog\lib\site-packages\urllib3\util\connection.py", line 84, in create_connection
    raise err
  File "D:\program_files\py_virtual_envs\env_myblog\lib\site-packages\urllib3\util\connection.py", line 74, in create_connection
    sock.connect(sa)
ConnectionRefusedError: [WinError 10061] 由于目标计算机积极拒绝，无法连接。

During handling of the above exception, another exception occurred:

Traceback (most recent call last):
  File "D:\program_files\py_virtual_envs\env_myblog\lib\site-packages\elasticsearch\connection\http_urllib3.py", line 242, in perform_request
    method, url, body, retries=Retry(False), headers=request_headers, **kw
  File "D:\program_files\py_virtual_envs\env_myblog\lib\site-packages\urllib3\connectionpool.py", line 720, in urlopen
    method, url, error=e, _pool=self, _stacktrace=sys.exc_info()[2]
  File "D:\program_files\py_virtual_envs\env_myblog\lib\site-packages\urllib3\util\retry.py", line 376, in increment
    raise six.reraise(type(error), error, _stacktrace)
  File "D:\program_files\py_virtual_envs\env_myblog\lib\site-packages\urllib3\packages\six.py", line 735, in reraise
    raise value
  File "D:\program_files\py_virtual_envs\env_myblog\lib\site-packages\urllib3\connectionpool.py", line 672, in urlopen
    chunked=chunked,
  File "D:\program_files\py_virtual_envs\env_myblog\lib\site-packages\urllib3\connectionpool.py", line 387, in _make_request
    conn.request(method, url, **httplib_request_kw)
  File "d:\program_files\python3.7.6\lib\http\client.py", line 1252, in request
    self._send_request(method, url, body, headers, encode_chunked)
  File "d:\program_files\python3.7.6\lib\http\client.py", line 1298, in _send_request
    self.endheaders(body, encode_chunked=encode_chunked)
  File "d:\program_files\python3.7.6\lib\http\client.py", line 1247, in endheaders
    self._send_output(message_body, encode_chunked=encode_chunked)
  File "d:\program_files\python3.7.6\lib\http\client.py", line 1026, in _send_output
    self.send(msg)
  File "d:\program_files\python3.7.6\lib\http\client.py", line 966, in send
    self.connect()
  File "D:\program_files\py_virtual_envs\env_myblog\lib\site-packages\urllib3\connection.py", line 184, in connect
    conn = self._new_conn()
  File "D:\program_files\py_virtual_envs\env_myblog\lib\site-packages\urllib3\connection.py", line 169, in _new_conn
    self, "Failed to establish a new connection: %s" % e
urllib3.exceptions.NewConnectionError: <urllib3.connection.HTTPConnection object at 0x00000231BD133808>: Failed to establish a new connection: [WinError 10061] 由于目标计算机积极拒绝，无法连接。
[2020-04-29 12:55:10,840][MainThread:4512][task_id:elasticsearch][base.py:150][WARNING][HEAD http://localhost:9200/ [status:N/A request:4.026s]]
Traceback (most recent call last):
  File "D:\program_files\py_virtual_envs\env_myblog\lib\site-packages\urllib3\connection.py", line 157, in _new_conn
    (self._dns_host, self.port), self.timeout, **extra_kw
  File "D:\program_files\py_virtual_envs\env_myblog\lib\site-packages\urllib3\util\connection.py", line 84, in create_connection
    raise err
  File "D:\program_files\py_virtual_envs\env_myblog\lib\site-packages\urllib3\util\connection.py", line 74, in create_connection
    sock.connect(sa)
ConnectionRefusedError: [WinError 10061] 由于目标计算机积极拒绝，无法连接。

During handling of the above exception, another exception occurred:

Traceback (most recent call last):
  File "D:\program_files\py_virtual_envs\env_myblog\lib\site-packages\elasticsearch\connection\http_urllib3.py", line 242, in perform_request
    method, url, body, retries=Retry(False), headers=request_headers, **kw
  File "D:\program_files\py_virtual_envs\env_myblog\lib\site-packages\urllib3\connectionpool.py", line 720, in urlopen
    method, url, error=e, _pool=self, _stacktrace=sys.exc_info()[2]
  File "D:\program_files\py_virtual_envs\env_myblog\lib\site-packages\urllib3\util\retry.py", line 376, in increment
    raise six.reraise(type(error), error, _stacktrace)
  File "D:\program_files\py_virtual_envs\env_myblog\lib\site-packages\urllib3\packages\six.py", line 735, in reraise
    raise value
  File "D:\program_files\py_virtual_envs\env_myblog\lib\site-packages\urllib3\connectionpool.py", line 672, in urlopen
    chunked=chunked,
  File "D:\program_files\py_virtual_envs\env_myblog\lib\site-packages\urllib3\connectionpool.py", line 387, in _make_request
    conn.request(method, url, **httplib_request_kw)
  File "d:\program_files\python3.7.6\lib\http\client.py", line 1252, in request
    self._send_request(method, url, body, headers, encode_chunked)
  File "d:\program_files\python3.7.6\lib\http\client.py", line 1298, in _send_request
    self.endheaders(body, encode_chunked=encode_chunked)
  File "d:\program_files\python3.7.6\lib\http\client.py", line 1247, in endheaders
    self._send_output(message_body, encode_chunked=encode_chunked)
  File "d:\program_files\python3.7.6\lib\http\client.py", line 1026, in _send_output
    self.send(msg)
  File "d:\program_files\python3.7.6\lib\http\client.py", line 966, in send
    self.connect()
  File "D:\program_files\py_virtual_envs\env_myblog\lib\site-packages\urllib3\connection.py", line 184, in connect
    conn = self._new_conn()
  File "D:\program_files\py_virtual_envs\env_myblog\lib\site-packages\urllib3\connection.py", line 169, in _new_conn
    self, "Failed to establish a new connection: %s" % e
urllib3.exceptions.NewConnectionError: <urllib3.connection.HTTPConnection object at 0x00000231BD14D688>: Failed to establish a new connection: [WinError 10061] 由于目标计算机积极拒绝，无法连接。
[2020-04-29 12:55:14,869][MainThread:4512][task_id:elasticsearch][base.py:150][WARNING][HEAD http://localhost:9200/ [status:N/A request:4.028s]]
Traceback (most recent call last):
  File "D:\program_files\py_virtual_envs\env_myblog\lib\site-packages\urllib3\connection.py", line 157, in _new_conn
    (self._dns_host, self.port), self.timeout, **extra_kw
  File "D:\program_files\py_virtual_envs\env_myblog\lib\site-packages\urllib3\util\connection.py", line 84, in create_connection
    raise err
  File "D:\program_files\py_virtual_envs\env_myblog\lib\site-packages\urllib3\util\connection.py", line 74, in create_connection
    sock.connect(sa)
ConnectionRefusedError: [WinError 10061] 由于目标计算机积极拒绝，无法连接。

During handling of the above exception, another exception occurred:

Traceback (most recent call last):
  File "D:\program_files\py_virtual_envs\env_myblog\lib\site-packages\elasticsearch\connection\http_urllib3.py", line 242, in perform_request
    method, url, body, retries=Retry(False), headers=request_headers, **kw
  File "D:\program_files\py_virtual_envs\env_myblog\lib\site-packages\urllib3\connectionpool.py", line 720, in urlopen
    method, url, error=e, _pool=self, _stacktrace=sys.exc_info()[2]
  File "D:\program_files\py_virtual_envs\env_myblog\lib\site-packages\urllib3\util\retry.py", line 376, in increment
    raise six.reraise(type(error), error, _stacktrace)
  File "D:\program_files\py_virtual_envs\env_myblog\lib\site-packages\urllib3\packages\six.py", line 735, in reraise
    raise value
  File "D:\program_files\py_virtual_envs\env_myblog\lib\site-packages\urllib3\connectionpool.py", line 672, in urlopen
    chunked=chunked,
  File "D:\program_files\py_virtual_envs\env_myblog\lib\site-packages\urllib3\connectionpool.py", line 387, in _make_request
    conn.request(method, url, **httplib_request_kw)
  File "d:\program_files\python3.7.6\lib\http\client.py", line 1252, in request
    self._send_request(method, url, body, headers, encode_chunked)
  File "d:\program_files\python3.7.6\lib\http\client.py", line 1298, in _send_request
    self.endheaders(body, encode_chunked=encode_chunked)
  File "d:\program_files\python3.7.6\lib\http\client.py", line 1247, in endheaders
    self._send_output(message_body, encode_chunked=encode_chunked)
  File "d:\program_files\python3.7.6\lib\http\client.py", line 1026, in _send_output
    self.send(msg)
  File "d:\program_files\python3.7.6\lib\http\client.py", line 966, in send
    self.connect()
  File "D:\program_files\py_virtual_envs\env_myblog\lib\site-packages\urllib3\connection.py", line 184, in connect
    conn = self._new_conn()
  File "D:\program_files\py_virtual_envs\env_myblog\lib\site-packages\urllib3\connection.py", line 169, in _new_conn
    self, "Failed to establish a new connection: %s" % e
urllib3.exceptions.NewConnectionError: <urllib3.connection.HTTPConnection object at 0x00000231BD1B4A88>: Failed to establish a new connection: [WinError 10061] 由于目标计算机积极拒绝，无法连接。
[2020-04-29 12:55:18,899][MainThread:4512][task_id:elasticsearch][base.py:150][WARNING][HEAD http://localhost:9200/ [status:N/A request:4.028s]]
Traceback (most recent call last):
  File "D:\program_files\py_virtual_envs\env_myblog\lib\site-packages\urllib3\connection.py", line 157, in _new_conn
    (self._dns_host, self.port), self.timeout, **extra_kw
  File "D:\program_files\py_virtual_envs\env_myblog\lib\site-packages\urllib3\util\connection.py", line 84, in create_connection
    raise err
  File "D:\program_files\py_virtual_envs\env_myblog\lib\site-packages\urllib3\util\connection.py", line 74, in create_connection
    sock.connect(sa)
ConnectionRefusedError: [WinError 10061] 由于目标计算机积极拒绝，无法连接。

During handling of the above exception, another exception occurred:

Traceback (most recent call last):
  File "D:\program_files\py_virtual_envs\env_myblog\lib\site-packages\elasticsearch\connection\http_urllib3.py", line 242, in perform_request
    method, url, body, retries=Retry(False), headers=request_headers, **kw
  File "D:\program_files\py_virtual_envs\env_myblog\lib\site-packages\urllib3\connectionpool.py", line 720, in urlopen
    method, url, error=e, _pool=self, _stacktrace=sys.exc_info()[2]
  File "D:\program_files\py_virtual_envs\env_myblog\lib\site-packages\urllib3\util\retry.py", line 376, in increment
    raise six.reraise(type(error), error, _stacktrace)
  File "D:\program_files\py_virtual_envs\env_myblog\lib\site-packages\urllib3\packages\six.py", line 735, in reraise
    raise value
  File "D:\program_files\py_virtual_envs\env_myblog\lib\site-packages\urllib3\connectionpool.py", line 672, in urlopen
    chunked=chunked,
  File "D:\program_files\py_virtual_envs\env_myblog\lib\site-packages\urllib3\connectionpool.py", line 387, in _make_request
    conn.request(method, url, **httplib_request_kw)
  File "d:\program_files\python3.7.6\lib\http\client.py", line 1252, in request
    self._send_request(method, url, body, headers, encode_chunked)
  File "d:\program_files\python3.7.6\lib\http\client.py", line 1298, in _send_request
    self.endheaders(body, encode_chunked=encode_chunked)
  File "d:\program_files\python3.7.6\lib\http\client.py", line 1247, in endheaders
    self._send_output(message_body, encode_chunked=encode_chunked)
  File "d:\program_files\python3.7.6\lib\http\client.py", line 1026, in _send_output
    self.send(msg)
  File "d:\program_files\python3.7.6\lib\http\client.py", line 966, in send
    self.connect()
  File "D:\program_files\py_virtual_envs\env_myblog\lib\site-packages\urllib3\connection.py", line 184, in connect
    conn = self._new_conn()
  File "D:\program_files\py_virtual_envs\env_myblog\lib\site-packages\urllib3\connection.py", line 169, in _new_conn
    self, "Failed to establish a new connection: %s" % e
urllib3.exceptions.NewConnectionError: <urllib3.connection.HTTPConnection object at 0x00000231BD1BD248>: Failed to establish a new connection: [WinError 10061] 由于目标计算机积极拒绝，无法连接。
[2020-04-29 12:55:22,924][MainThread:4512][task_id:elasticsearch][base.py:150][WARNING][HEAD http://localhost:9200/ [status:N/A request:4.022s]]
Traceback (most recent call last):
  File "D:\program_files\py_virtual_envs\env_myblog\lib\site-packages\urllib3\connection.py", line 157, in _new_conn
    (self._dns_host, self.port), self.timeout, **extra_kw
  File "D:\program_files\py_virtual_envs\env_myblog\lib\site-packages\urllib3\util\connection.py", line 84, in create_connection
    raise err
  File "D:\program_files\py_virtual_envs\env_myblog\lib\site-packages\urllib3\util\connection.py", line 74, in create_connection
    sock.connect(sa)
ConnectionRefusedError: [WinError 10061] 由于目标计算机积极拒绝，无法连接。

During handling of the above exception, another exception occurred:

Traceback (most recent call last):
  File "D:\program_files\py_virtual_envs\env_myblog\lib\site-packages\elasticsearch\connection\http_urllib3.py", line 242, in perform_request
    method, url, body, retries=Retry(False), headers=request_headers, **kw
  File "D:\program_files\py_virtual_envs\env_myblog\lib\site-packages\urllib3\connectionpool.py", line 720, in urlopen
    method, url, error=e, _pool=self, _stacktrace=sys.exc_info()[2]
  File "D:\program_files\py_virtual_envs\env_myblog\lib\site-packages\urllib3\util\retry.py", line 376, in increment
    raise six.reraise(type(error), error, _stacktrace)
  File "D:\program_files\py_virtual_envs\env_myblog\lib\site-packages\urllib3\packages\six.py", line 735, in reraise
    raise value
  File "D:\program_files\py_virtual_envs\env_myblog\lib\site-packages\urllib3\connectionpool.py", line 672, in urlopen
    chunked=chunked,
  File "D:\program_files\py_virtual_envs\env_myblog\lib\site-packages\urllib3\connectionpool.py", line 387, in _make_request
    conn.request(method, url, **httplib_request_kw)
  File "d:\program_files\python3.7.6\lib\http\client.py", line 1252, in request
    self._send_request(method, url, body, headers, encode_chunked)
  File "d:\program_files\python3.7.6\lib\http\client.py", line 1298, in _send_request
    self.endheaders(body, encode_chunked=encode_chunked)
  File "d:\program_files\python3.7.6\lib\http\client.py", line 1247, in endheaders
    self._send_output(message_body, encode_chunked=encode_chunked)
  File "d:\program_files\python3.7.6\lib\http\client.py", line 1026, in _send_output
    self.send(msg)
  File "d:\program_files\python3.7.6\lib\http\client.py", line 966, in send
    self.connect()
  File "D:\program_files\py_virtual_envs\env_myblog\lib\site-packages\urllib3\connection.py", line 184, in connect
    conn = self._new_conn()
  File "D:\program_files\py_virtual_envs\env_myblog\lib\site-packages\urllib3\connection.py", line 169, in _new_conn
    self, "Failed to establish a new connection: %s" % e
urllib3.exceptions.NewConnectionError: <urllib3.connection.HTTPConnection object at 0x00000231BD1BDA88>: Failed to establish a new connection: [WinError 10061] 由于目标计算机积极拒绝，无法连接。
[2020-04-29 12:55:26,946][MainThread:4512][task_id:elasticsearch][base.py:150][WARNING][HEAD http://localhost:9200/ [status:N/A request:4.021s]]
Traceback (most recent call last):
  File "D:\program_files\py_virtual_envs\env_myblog\lib\site-packages\urllib3\connection.py", line 157, in _new_conn
    (self._dns_host, self.port), self.timeout, **extra_kw
  File "D:\program_files\py_virtual_envs\env_myblog\lib\site-packages\urllib3\util\connection.py", line 84, in create_connection
    raise err
  File "D:\program_files\py_virtual_envs\env_myblog\lib\site-packages\urllib3\util\connection.py", line 74, in create_connection
    sock.connect(sa)
ConnectionRefusedError: [WinError 10061] 由于目标计算机积极拒绝，无法连接。

During handling of the above exception, another exception occurred:

Traceback (most recent call last):
  File "D:\program_files\py_virtual_envs\env_myblog\lib\site-packages\elasticsearch\connection\http_urllib3.py", line 242, in perform_request
    method, url, body, retries=Retry(False), headers=request_headers, **kw
  File "D:\program_files\py_virtual_envs\env_myblog\lib\site-packages\urllib3\connectionpool.py", line 720, in urlopen
    method, url, error=e, _pool=self, _stacktrace=sys.exc_info()[2]
  File "D:\program_files\py_virtual_envs\env_myblog\lib\site-packages\urllib3\util\retry.py", line 376, in increment
    raise six.reraise(type(error), error, _stacktrace)
  File "D:\program_files\py_virtual_envs\env_myblog\lib\site-packages\urllib3\packages\six.py", line 735, in reraise
    raise value
  File "D:\program_files\py_virtual_envs\env_myblog\lib\site-packages\urllib3\connectionpool.py", line 672, in urlopen
    chunked=chunked,
  File "D:\program_files\py_virtual_envs\env_myblog\lib\site-packages\urllib3\connectionpool.py", line 387, in _make_request
    conn.request(method, url, **httplib_request_kw)
  File "d:\program_files\python3.7.6\lib\http\client.py", line 1252, in request
    self._send_request(method, url, body, headers, encode_chunked)
  File "d:\program_files\python3.7.6\lib\http\client.py", line 1298, in _send_request
    self.endheaders(body, encode_chunked=encode_chunked)
  File "d:\program_files\python3.7.6\lib\http\client.py", line 1247, in endheaders
    self._send_output(message_body, encode_chunked=encode_chunked)
  File "d:\program_files\python3.7.6\lib\http\client.py", line 1026, in _send_output
    self.send(msg)
  File "d:\program_files\python3.7.6\lib\http\client.py", line 966, in send
    self.connect()
  File "D:\program_files\py_virtual_envs\env_myblog\lib\site-packages\urllib3\connection.py", line 184, in connect
    conn = self._new_conn()
  File "D:\program_files\py_virtual_envs\env_myblog\lib\site-packages\urllib3\connection.py", line 169, in _new_conn
    self, "Failed to establish a new connection: %s" % e
urllib3.exceptions.NewConnectionError: <urllib3.connection.HTTPConnection object at 0x00000231BD1C12C8>: Failed to establish a new connection: [WinError 10061] 由于目标计算机积极拒绝，无法连接。
[2020-04-29 12:55:30,579][MainThread:4512][task_id:elasticsearch][base.py:122][INFO][HEAD http://localhost:9200/ [status:200 request:3.632s]]
[2020-04-29 12:55:30,591][MainThread:4512][task_id:elasticsearch][base.py:122][INFO][HEAD http://localhost:9200/blog [status:200 request:0.011s]]
[2020-04-29 12:55:30,594][MainThread:4512][task_id:elasticsearch][base.py:122][INFO][HEAD http://localhost:9200/ [status:200 request:0.002s]]
[2020-04-29 12:55:30,597][MainThread:4512][task_id:elasticsearch][base.py:122][INFO][HEAD http://localhost:9200/suggestion_db [status:200 request:0.003s]]
[2020-04-29 12:56:26,154][MainThread:12100][task_id:elasticsearch][base.py:122][INFO][HEAD http://localhost:9200/ [status:200 request:0.008s]]
[2020-04-29 12:56:26,156][MainThread:12100][task_id:elasticsearch][base.py:122][INFO][HEAD http://localhost:9200/ [status:200 request:0.001s]]
[2020-04-29 12:56:26,158][MainThread:12100][task_id:elasticsearch][base.py:122][INFO][HEAD http://localhost:9200/blog [status:200 request:0.001s]]
[2020-04-29 12:56:26,159][MainThread:12100][task_id:elasticsearch][base.py:122][INFO][HEAD http://localhost:9200/ [status:200 request:0.001s]]
[2020-04-29 12:56:26,163][MainThread:12100][task_id:elasticsearch][base.py:122][INFO][HEAD http://localhost:9200/suggestion_db [status:200 request:0.002s]]
[2020-04-29 12:58:07,576][MainThread:6276][task_id:elasticsearch][base.py:122][INFO][HEAD http://localhost:9200/ [status:200 request:0.008s]]
[2020-04-29 12:58:07,578][MainThread:6276][task_id:elasticsearch][base.py:122][INFO][HEAD http://localhost:9200/ [status:200 request:0.001s]]
[2020-04-29 12:58:07,580][MainThread:6276][task_id:elasticsearch][base.py:122][INFO][HEAD http://localhost:9200/blog [status:200 request:0.002s]]
[2020-04-29 12:58:07,581][MainThread:6276][task_id:elasticsearch][base.py:122][INFO][HEAD http://localhost:9200/ [status:200 request:0.001s]]
[2020-04-29 12:58:07,583][MainThread:6276][task_id:elasticsearch][base.py:122][INFO][HEAD http://localhost:9200/suggestion_db [status:200 request:0.002s]]
